Workbook

Sheet WARNING NOTE
A6: WARNING NOTICE
A8: THIS CHECKLIST HAS FORMULAS THAT AUTOMATICALLY CALCULATE SUMMATIONS AND ROLL-UPS OF COMPLIANCE STATE. THESE FORMULAS MAY HAVE ERRORS THAT HAVE NOT BEEN DETECTED. PLEASE BE ADVISED THAT DUE TO THE POTENTIAL FOR AN ERROR IT IS RECOMMENDED THAT A MANUAL VERIFICATION BE PERFORMED BY THE PERSON OR ORGANIZATION FILLING OUT THE CHECKLIST TO ENSURE THAT THE CHECKLIST ACCURATELY REFLECTS THE STATE OF COMPLIANCE FOR THE OMS ELEMENT IN QUESTION.
A10: Notes for the User:
A12: This workbook has protection applied to preserve formulas and cross referencing.
A14: User input is only required/allowed in the blue shaded cells of each worksheet, except for the Cover, Abstract and Rev Table, which are user editable.

Sheet Cover
A3: <REQUIRED: MISSION PACKAGE CHECKLIST TITLE>
A4: <OPTIONAL: Organization CDRL Number>
A5: <OPTIONAL: Organization Logo>
A6: Prepared By:
A7: <REQUIRED: Organization>
A8: <OPTIONAL: Address>
A10: DISCLAIMER: The discussion of non-federal entities, methods, products, or services does not imply any endorsement by the United States Government, the Department of Defense, or the Department of the Air Force.
A11: Distribution Statement A. Approved for public release: distribution is unlimited.

Sheet Abstract
A1: ABSTRACT
A2: < The abstract is REQUIRED and is a brief summary of the document that follows and is used to help the reader quickly ascertain the document's purpose and overall content. >
A3: < Before attempting to fill out this checklist, the Mission Package compliance assessor should have access to the referenced Mission Package Worksheet (MPW) and Mission Package Description Document (MPDD) for the Mission Package, as well as the individual checklists for the Platform, Subsystems, Services, and Isolators in the Mission Package. >
A4: This Mission Package Checklist complies with the OMS Standard Version 2.5, OMSC-STD-001, Revision M, 22 January 2026.

Sheet Rev
A2: REVISION RECORD
A4: REVISION | B4: DATE | C4: DESCRIPTION
A5: - | B5: dd-mmm-yy | C5: Original

Sheet Tier Compliance
A1: Tier Compliance at: | B1: =IF(E46=TRUE,"Tier 3", IF(E34=TRUE,"Tier 2",IF(E15=TRUE,"Tier 1", "Not Tier Compliant"))) -> Not Tier Compliant
A3: Mission Package Tier 1 RQMTS
A4: RQMT ID | B4: RQMT Topic | C4: Subordinate RQMTs | D4: Subordinate RQMTs Topic | E4: RQMT Met?
A5: STD-000101 Tier 1, 2, 3 | B5: Provide Tier 1 Platform | C5: N/A | D5: N/A | E5: ='Mission Package RQMT Checklist'!C2 -> FALSE
A6: STD-009208 Tier 1, 2, 3 | B6: Contain Tier 1 Compliance OMS Architecture Elements | C6: N/A | D6: N/A | E6: ='Mission Package RQMT Checklist'!C4 -> FALSE
A7: STD-000102 Tier 1, 2, 3 | B7: Provide Tier 1 Service | C7: N/A | D7: N/A | E7: ='Mission Package RQMT Checklist'!C6 -> FALSE
A8: STD-000103 Tier 1, 2, 3 | B8: Provide Tier 1 Subsystem | C8: N/A | D8: N/A | E8: ='Mission Package RQMT Checklist'!C10 -> FALSE
A9: STD-000104 Tier 1, 2, 3 | B9: Provide Isolator | C9: N/A | D9: N/A | E9: ='Mission Package RQMT Checklist'!C14 -> FALSE
A10: STD-005004 Tier 1, 2, 3 | B10: Provide NFS and/or FTP | C10: N/A | D10: N/A | E10: ='Mission Package RQMT Checklist'!C16 -> FALSE
A11: STD-009924 Tier 1, 2, 3 | B11: Document Units of Replaceability | C11: N/A | D11: N/A | E11: ='Mission Package RQMT Checklist'!C18 -> FALSE
A12: STD-008124 Tier 1, 2, 3 | B12: Mission Package Description Document (MPDD) Required | C12: N/A | D12: N/A | E12: ='Mission Package RQMT Checklist'!C20 -> FALSE
A13: STD-010180 Tier 1, 2, 3 | B13: Document Cybersecurity Posture | C13: N/A | D13: N/A | E13: ='Mission Package RQMT Checklist'!C36 -> FALSE
A14: STD-009714 Tier 1, 2, 3 | B14: Document Cybersecurity posture | C14: N/A | D14: N/A | E14: ='Mission Package RQMT Checklist'!C38 -> FALSE
D15: Tier 1 RQMTs Met? | E15: =AND(E5:E14) -> FALSE
A17: Mission Package Tier 2 RQMTS
A18: RQMT ID | B18: RQMT Topic | C18: Subordinate RQMTs | D18: Subordinate RQMTs Topic | E18: RQMT Met?
A19: STD-008675 Tier 2, 3 | B19: Meet Tier 1 Requirements | C19: list below | D19: list below | E19: ='Mission Package RQMT Checklist'!C40 -> FALSE
C20: STD-000101 Tier 1, 2, 3 | D20: Provide Tier 1 Platform | E20: ='Mission Package RQMT Checklist'!C2 -> FALSE
C21: STD-000102 Tier 1, 2, 3 | D21: Provide Tier 1 Service | E21: ='Mission Package RQMT Checklist'!C6 -> FALSE
C22: STD-000103 Tier 1, 2, 3 | D22: Provide Tier 1 Subsystem | E22: ='Mission Package RQMT Checklist'!C10 -> FALSE
C23: STD-000104 Tier 1, 2, 3 | D23: Provide Isolator | E23: ='Mission Package RQMT Checklist'!C14 -> FALSE
C24: STD-005004 Tier 1, 2, 3 | D24: Provide NFS and/or FTP | E24: ='Mission Package RQMT Checklist'!C16 -> FALSE
C25: STD-008124 Tier 1, 2, 3 | D25: Mission Package Description Document (MPDD) Required | E25: ='Mission Package RQMT Checklist'!C20 -> FALSE
C26: STD-009208 Tier 1, 2, 3 | D26: Contain Tier 1 Compliance OMS Architecture Elements | E26: ='Mission Package RQMT Checklist'!C4 -> FALSE
C27: STD-009714 Tier 1, 2, 3 | D27: Document Cybersecurity posture | E27: ='Mission Package RQMT Checklist'!C38 -> FALSE
C28: STD-009924 Tier 1, 2, 3 | D28: Document Units of Replaceability | E28: ='Mission Package RQMT Checklist'!C18 -> FALSE
C29: STD-010180 Tier 1, 2, 3 | D29: Document Cybersecurity Posture | E29: ='Mission Package RQMT Checklist'!C36 -> FALSE
A30: STD-000107 Tier 2, 3 | B30: Provide Tier 2 Platform | C30: N/A | D30: N/A | E30: ='Mission Package RQMT Checklist'!C41 -> FALSE
A31: STD-009210 Tier 2, 3 | B31: Contain Tier 2 Compliance OMS Architecture Elements | C31: N/A | D31: N/A | E31: ='Mission Package RQMT Checklist'!C43 -> FALSE
A32: STD-000108 Tier 2, 3 | B32: Provide Tier 2 Services | C32: N/A | D32: N/A | E32: ='Mission Package RQMT Checklist'!C45 -> FALSE
A33: STD-000109 Tier 2, 3 | B33: Provide Tier 2 Subsystems | C33: N/A | D33: N/A | E33: ='Mission Package RQMT Checklist'!C49 -> FALSE
D34: Tier 2 RQMTs Met? | E34: =AND(E19:E33) -> FALSE
A36: Mission Package Tier 3 RQMTS
A37: RQMT ID | B37: RQMT Topic | C37: Subordinate RQMTs | D37: Subordinate RQMTs Topic | E37: RQMT Met?
A38: STD-008676 Tier 3 | B38: Meet Tier 2 Requirements | C38: list below | D38: list below | E38: ='Mission Package RQMT Checklist'!C53 -> FALSE
C39: STD-000107 Tier 2, 3 | D39: Provide Tier 2 Platform | E39: ='Mission Package RQMT Checklist'!C41 -> FALSE
C40: STD-000108 Tier 2, 3 | D40: Provide Tier 2 Services | E40: ='Mission Package RQMT Checklist'!C45 -> FALSE
C41: STD-000109 Tier 2, 3 | D41: Provide Tier 2 Subsystems | E41: ='Mission Package RQMT Checklist'!C49 -> FALSE
C42: STD-008675 Tier 2, 3 | D42: Meet Tier 1 Requirements | E42: ='Mission Package RQMT Checklist'!C40 -> FALSE
C43: STD-009210 Tier 2, 3 | D43: Contain Tier 2 Compliance OMS Architecture Elements | E43: ='Mission Package RQMT Checklist'!C43 -> FALSE
...

Sheet Mission Package RQMT Checklist
A1: RQMT ID | B1: RQMT Text | C1: RQMT Met? | D1: Clarification | E1: Subordinate RQMTS | F1: Sub RQMTS Met? | G1: VR List | H1: All VRs Met? | I1: Verification Requirement (VR) | J1: VR Tier | K1: Guidance | L1: AC List | M1: VR Met? | N1: Acceptance Criteria (AC) | O1: Assessed Article | P1: AC Met? | Q1: N/A Rationale
A2: STD-000101 Tier 1, 2, 3 | B2: RQMT STD-000101 [A Tier 1 OMS Mission Package shall provide an OMS Platform assessed to at least Tier 1 compliance.] | C2: =AND((OR(IF(F2=TRUE,TRUE,FALSE),IF(F2="N/A",TRUE,FALSE))),H2=TRUE) -> FALSE | F2: N/A | G2: (-1) | H2: =AND(M2) -> FALSE | I2: STD-000101 (-1): This requirement is verified by inspection of compliance artifacts showing that the OMS Mission Package includes an OMS Platform assessed to at least Tier 1 compliance. | J2: 1, 2, 3 | K2: A complete “as built” version of the information in the Mission Package Worksheet (MPW) per OMSC-TMP-006, is referenced by the “Mission Package Description” section of the MPDD and documents the Tier compliance of the OMS Mission Package and each Platform, Subsystem, Service, and Isolator in the OMS Mission Package. | L2: (-1)_1 | M2: =AND(OR(IF(P2=TRUE,TRUE,FALSE),(IF(P2="N/A",NOT(ISBLANK(Q2))))),(OR(IF(P3=TRUE,TRUE,FALSE),(IF(P3="N/A",NOT(ISBLANK(Q3))))))) -> FALSE | N2: STD-000101 (-1)_1: The MPDD documents that the OMS Mission Package includes an OMS Platform that is at least Tier 1 compliant. | O2: Mission Package Description Document (MPDD) | P2: AC 1-1 Met?
N3: STD-000101 (-1)_2: The OMS Platform listed in the MPDD has a Platform Checklist that indicates the Platform is assessed to at least Tier 1 compliance, which is recorded in the [[Tier Compliance]] tab of the Platform Checklist. | O3: Platform Checklist | P3: AC 1-2 Met?
A4: STD-009208 Tier 1, 2, 3 | B4: RQMT STD-009208 [A Tier 1 OMS Mission Package shall contain only OMS Architecture Elements assessed to at least Tier 1 compliance.] | C4: =AND((OR(IF(F4=TRUE,TRUE,FALSE),IF(F4="N/A",TRUE,FALSE))),H4=TRUE) -> FALSE | D4: In this context, OMS Architecture Elements assessed for compliance in the Mission Package are defined as a Platform, Services, and Subsystems. | F4: N/A | G4: (-1) | H4: =AND(M4) -> FALSE | I4: STD-009208 (-1): This requirement is verified by inspection of compliance artifacts showing that each Platform, Subsystem, and Service included in the OMS Mission Package is assessed to at least Tier 1 compliance. | J4: 1, 2, 3 | K4: A complete “as built” version of the information in the Mission Package Worksheet (MPW) per OMSC-TMP-006, is referenced by the “Mission Package Description” section of the MPDD and documents the Tier compliance of the OMS Mission Package and each Platform, Subsystem, Service, and Isolator in the OMS Mission Package. An OMS Mission Package can only achieve an assessment Tier that is no higher than the lowest tier of the following assessed Architecture Elements in the Mission Package: Platform, Subsystems, and Services. | L4: (-1)_1 (-1)_2 | M4: =AND(OR(IF(P4=TRUE,TRUE,FALSE),(IF(P4="N/A",NOT(ISBLANK(Q4))))),(OR(IF(P5=TRUE,TRUE,FALSE),(IF(P5="N/A",NOT(ISBLANK(Q5))))))) -> FALSE | N4: STD-009208 (-1)_1: The MPDD documents that each OMS Architecture Element (Platform, Subsystem, and Service) included in the OMS Mission Package is at least Tier 1 compliant. | O4: Mission Package Description Document (MPDD) | P4: AC 1-1 Met?
N5: STD-009208 (-1)_2: Each OMS Architecture Element (Platform, Subsystem, and Service) listed in the MPDD has a corresponding checklist that indicates the OMS Architecture Element is assessed to at least Tier 1 compliance, which is recorded in the [[Tier Compliance]] tab of each checklist. | O5: Corresponding Checklist | P5: AC 1-2 Met?
A6: STD-000102 Tier 1, 2, 3 | B6: RQMT STD-000102 [A Tier 1 OMS Mission Package shall provide at least one applicable Tier 1 compliant Service Capability from the “Service Capability List for Compliance” section.] | C6: =AND((OR(IF(F6=TRUE,TRUE,FALSE),IF(F6="N/A",TRUE,FALSE))),H6=TRUE) -> FALSE | D6: In the context of this requirement, the term “applicable” means those Services that are identified as an OMS Service in the Mission Package Worksheet for a program, that are described in the “Service Capability List for Compliance.” If the Mission Package Worksheet for a program does not include any Services that are described in this list, then there are no “applicable” Services and the requirement is satisfied. | F6: N/A | G6: (-1) (-2) | H6: =AND(M6,M8) -> FALSE | I6: STD-000102 (-1): This requirement is verified by inspection of the Mission Package Description Document (MPDD), showing that the OMS Mission Package includes one or more Services, described in the “Service Capability List for Compliance,” that are at least Tier 1 compliant. | J6: 1, 2, 3 | K6: It is possible that a Tier 1 OMS Mission Package does not include any Services that are described in the “Service Capability List for Compliance.” If the Mission Package Worksheet provided by the adopting program does not require any Services that are described in the “Service Capability List for Compliance,” then there are no “applicable” Services and the requirement is satisfied. A complete “as built” version of the information in the Mission Package Worksheet (MPW) per OMSC-TMP-006, is referenced by the “Mission Package Description” section of the MPDD and documents the Tier compliance of the OMS Mission Package and each Platform, Subsystem, Service, and Isolator in the OMS Mission Package. | L6: (-1)_1 (-1)_2 | M6: =IF(P6=TRUE,TRUE,(AND((OR(IF(P7=TRUE,TRUE,FALSE),(IF(P7="N/A",NOT(ISBLANK(Q7))))))))) -> FALSE | N6: STD-000102 (-1)_1: If the adopting program does not require any Services that are described in the “Service Capability List for Compliance,” then this VR is satisfied. | O6: Mission Package Worksheet | P6: AC 1-1 Met?
N7: STD-000102 (-1)_2: The MPDD documents that the OMS Mission Package includes at least one Service from the “Service Capability List for Compliance” that is at least Tier 1 compliant. | O7: Mission Package Description Document (MPDD) | P7: AC 1-2 Met?
I8: STD-000102 (-2): If the Mission Package Worksheet per OMSC-TMP-006 from the adopting program requires additional or specific Service capabilities to be at least Tier 1 compliant, then this requirement is verified by inspection of the Mission Package Description Document (MPDD), showing that each additional program-specified Service is at least Tier 1 compliant. | J8: 1, 2, 3 | K8: An adopting program may require additional Services from the “Service Capability List for Compliance” to be Tier 1 compliant. A complete “as built” version of the information in the Mission Package Worksheet (MPW) per OMSC-TMP-006, is referenced by the “Mission Package Description” section of the MPDD and documents the Tier compliance of the OMS Mission Package and each Platform, Subsystem, Service, and Isolator in the OMS Mission Package. | L8: (-2)_1 (-2)_2 | M8: =IF(P8=TRUE,TRUE,(AND((OR(IF(P9=TRUE,TRUE,FALSE),(IF(P9="N/A",NOT(ISBLANK(Q9))))))))) -> FALSE | N8: STD-000102 (-2)_1: If the adopting program does not require additional or specific Services to be Tier 1 compliant, then this VR is satisfied. | O8: Mission Package Worksheet | P8: AC 2-1 Met?
N9: STD-000102 (-2)_2: The MPDD shows that each additional Service required by the program to be Tier 1 compliant is documented as being at least Tier 1 compliant. | O9: Mission Package Description Document (MPDD) | P9: AC 2-2 Met?
A10: STD-000103 Tier 1, 2, 3 | B10: RQMT STD-000103 [A Tier 1 OMS Mission Package shall provide at least one applicable Tier 1 compliant Subsystem from the “Subsystem List for Compliance” section.] | C10: =AND((OR(IF(F10=TRUE,TRUE,FALSE),IF(F10="N/A",TRUE,FALSE))),H10=TRUE) -> FALSE | D10: In the context of this requirement, the term “applicable” means those Subsystems that are identified as an OMS Subsystem in the Mission Package Worksheet for a program, that are described in the “Subsystem List for Compliance.” If the Mission Package Worksheet for a program does not include any Subsystems that are described in this list, then there are no “applicable” Subsystems and the requirement is satisfied. | F10: N/A | G10: (-1) (-2) | H10: =AND(M10,M12) -> FALSE | I10: STD-000103 (-1): This requirement is verified by inspection of the Mission Package Description Document (MPDD), showing that the OMS Mission Package includes one or more Subsystems described in the “Subsystem List for Compliance” that are at least Tier 1 compliant. | J10: 1, 2, 3 | K10: It is possible that a Tier 1 OMS Mission Package does not include any Subsystems that are described in the “Subsystem List for Compliance.” If the Mission Package Worksheet provided by the adopting program does not include any Subsystems that are described in the “Subsystem List for Compliance,” then there are no “applicable” Subsystems and the requirement is satisfied. A complete “as built” version of the information in the Mission Package Worksheet (MPW) per OMSC-TMP-006, is referenced by the “Mission Package Description” section of the MPDD and documents the Tier compliance of the OMS Mission Package and each Platform, Subsystem, Service, and Isolator in the OMS Mission Package. | L10: (-1)_1 (-1)_2 | M10: =IF(P10=TRUE,TRUE,(AND((OR(IF(P11=TRUE,TRUE,FALSE),(IF(P11="N/A",NOT(ISBLANK(Q11))))))))) -> FALSE | N10: STD-000103 (-1)_1: If the adopting program does not require any Subsystems described in the “Subsystem List for Compliance,” then this VR is satisfied. | O10: Mission Package Worksheet | P10: AC 1-1 Met?
N11: STD-000103 (-1)_2: The MPDD documents that the OMS Mission Package includes at least one Subsystem from the “Subsystem List for Compliance” that is at least Tier 1 compliant. | O11: Mission Package Description Document (MPDD) | P11: AC 1-2 Met?
I12: STD-000103 (-2): If the Mission Package Worksheet per OMSC-TMP-006 from the adopting program requires additional or specific Subsystems to be at least Tier 1 compliant, then this requirement is verified by inspection of the Mission Package Description Document (MPDD), showing that each additional program-specified Subsystem is at least Tier 1 compliant. | J12: 1, 2, 3 | K12: An adopting program may require additional Subsystems from the “Subsystem List for Compliance” to be Tier 1 compliant. A complete “as built” version of the information in the Mission Package Worksheet (MPW) per OMSC-TMP-006, is referenced by the “Mission Package Description” section of the MPDD and documents the Tier compliance of the OMS Mission Package and each Platform, Subsystem, Service, and Isolator in the OMS Mission Package. | L12: (-2)_1 (-2)_2 | M12: =IF(P12=TRUE,TRUE,(AND((OR(IF(P13=TRUE,TRUE,FALSE),(IF(P13="N/A",NOT(ISBLANK(Q13))))))))) -> FALSE | N12: STD-000103 (-2)_1: If the adopting program does not require additional or specific Subsystems to be Tier 1 compliant, then this VR is satisfied. | O12: Mission Package Worksheet | P12: AC 2-1 Met?
N13: STD-000103 (-2)_2: The MPDD shows that each additional Subsystem required by the program to be Tier 1 compliant is documented as being at least Tier 1 compliant. | O13: Mission Package Description Document (MPDD) | P13: AC 2-2 Met?
A14: STD-000104 Tier 1, 2, 3 | B14: RQMT STD-000104 [A Tier 1 OMS Mission Package shall provide at least one Isolator if applicable.] | C14: =AND((OR(IF(F14=TRUE,TRUE,FALSE),IF(F14="N/A",TRUE,FALSE))),H14=TRUE) -> FALSE | F14: N/A | G14: (-1) | H14: =AND(M14) -> FALSE | I14: STD-000104 (-1): This requirement is verified by inspection of Mission Package Description Document (MPDD), showing that the OMS Mission Package includes one or more Isolators. | J14: 1, 2, 3 | K14: Not all Mission Packages require isolation. Ground stations, Roll-on/Roll-off systems, ground stations, and lab configurations may not require isolation. Isolation is required to enforce Safety of Flight, Nuclear, and other flight certifications. | L14: (-1)_1 (-1)_2 | M14: =IF(P14=TRUE,TRUE,(AND((OR(IF(P15=TRUE,TRUE,FALSE),(IF(P15="N/A",NOT(ISBLANK(Q15))))))))) -> FALSE | N14: STD-000104 (-1)_1: If the Mission Package does not require isolation, then this VR is satisfied. | O14: Mission Package Worksheet | P14: AC 1-1 Met?
N15: STD-000104 (-1)_2: The MPDD documents that the OMS Mission Package includes at least one Isolator. | O15: Mission Package Description Document (MPDD) | P15: AC 1-2 Met?
A16: STD-005004 Tier 1, 2, 3 | B16: RQMT STD-005004 [A Tier 1 OMS Mission Package shall provide NFS and/or FTP support for the allowed protocols identified in the “Data Transfer Formats, APIs, and Protocols” table.] | C16: =AND((OR(IF(F16=TRUE,TRUE,FALSE),IF(F16="N/A",TRUE,FALSE))),H16=TRUE) -> FALSE | F16: N/A | G16: (-1) | H16: =AND(M16) -> FALSE | I16: STD-005004 (-1): This requirement is verified by inspection of the Mission Package Description Document (MPDD), showing where the NFS and/or FTP servers are located within the OMS Mission Package. | J16: 1, 2, 3 | K16: This requirement is allocated to the OMS Mission Package to allow for either the OMS Platform or an OMS Subsystem to provide the NFS and/or FTP servers. The servers are then documented in the Platform Description Document (PDD) or the Subsystem Description Document (SDD) as appropriate. The MPDD documents the location of the servers and cross references the applicable PDD or SDD. | L16: (-1)_1 (-1)_2 | M16: =AND(OR(IF(P16=TRUE,TRUE,FALSE),(IF(P16="N/A",NOT(ISBLANK(Q16))))),(OR(IF(P17=TRUE,TRUE,FALSE),(IF(P17="N/A",NOT(ISBLANK(Q17))))))) -> FALSE | N16: STD-005004 (-1)_1: The MPDD documents the location of the NFS and/or FTP servers for the Mission Package. | O16: Mission Package Description Document (MPDD) | P16: AC 1-1 Met?
N17: STD-005004 (-1)_2: The MPDD identifies the PDD for the Platform or the SDD for the Subsystem that provides the NFS and/or FTP servers for the OMS Mission Package. | O17: Mission Package Description Document (MPDD) | P17: AC 1-2 Met?
A18: STD-009924 Tier 1, 2, 3 | B18: RQMT STD-009924 [A Tier 1 OMS Mission Package shall document its Units of Replaceability in a non-proprietary Mission Package Worksheet in accordance with the OMS Mission Package Worksheet Template.] | C18: =AND((OR(IF(F18=TRUE,TRUE,FALSE),IF(F18="N/A",TRUE,FALSE))),H18=TRUE) -> FALSE | F18: N/A | G18: (-1) | H18: =AND(M18) -> FALSE | I18: STD-009924 (-1): This requirement is verified by inspection of the Mission Package Worksheet (MPW) showing that the MPW is complete and complies with the current version of the MPW Template, OMSC-TMP-006, and that the delivered MPW does not include proprietary labels. | J18: 1, 2, 3 | K18: The MPW documents the contents of the Mission Package, including the Mission Package itself as well as every OMS Subsystem, OMS Service, and OMS Isolator in the Mission Package. “Current Version” in this context refers to the version of the MPW Template specified in the OMS Standard against which compliance is being measured. Although the MPW may contain references to proprietary documentation, the MPW itself must be non-proprietary. The MPW documents CSRCs, which are typically assigned by the program. If the Mission Package does not have a program-assigned Cybersecurity requirement, “N/A” is a valid assignment in the CSRC field. | L18: (-1)_1 (-1)_2 | M18: =AND(OR(IF(P18=TRUE,TRUE,FALSE),(IF(P18="N/A",NOT(ISBLANK(Q18))))),(OR(IF(P19=TRUE,TRUE,FALSE),(IF(P19="N/A",NOT(ISBLANK(Q19))))))) -> FALSE | N18: STD-009924 (-1)_1: The Mission Package Worksheet referenced in the MPDD is complete and complies with the current version of the MPW Template. | O18: Mission Package Worksheet | P18: AC 1-1 Met?
N19: STD-009924 (-1)_2: The delivered MPW has no proprietary labels applied to any of its pages. | O19: Mission Package Worksheet | P19: AC 1-2 Met?
A20: STD-008124 Tier 1, 2, 3 | B20: RQMT STD-008124 [A Tier 1 OMS Mission Package shall be documented in a non-proprietary Mission Package Description Document in accordance with the OMS Mission Package Description Document Template.] | C20: =AND((OR(IF(F20=TRUE,TRUE,FALSE),IF(F20="N/A",TRUE,FALSE))),H20=TRUE) -> FALSE | F20: N/A | G20: (-1) (-2) (-3) (-4) (-5) (-6) (-7) (-8) | H20: =AND(M20,M22,M24,M26,M28,M30,M32,M34) -> FALSE | I20: STD-008124 (-1): This requirement is verified by inspection of the Mission Package Description Document (MPDD) showing that the MPDD is complete and complies with the current version of the MPDD Template, OMSC-TMP-007 and that the delivered MPDD does not include proprietary labels; inspection results are recorded in the [[MPDD]] tab of the Mission Package Checklist, OMSC-CHK-002. | J20: 1, 2, 3 | K20: “Current Version” in this context refers to the version of the MPDD Template specified in the OMS Standard against which compliance is being measured. Although the MPDD may contain references to proprietary documentation, the MPDD itself must be non-proprietary. | L20: (-1)_1 (-1)_2 | M20: =AND(OR(IF(P20=TRUE,TRUE,FALSE),(IF(P20="N/A",NOT(ISBLANK(Q20))))),(OR(IF(P21=TRUE,TRUE,FALSE),(IF(P21="N/A",NOT(ISBLANK(Q21))))))) -> FALSE | N20: STD-008124 (-1)_1: The [[MPDD]] tab of the Mission Package Checklist shows that the MPDD is complete and complies with the current version of the MPDD Template. | O20: Mission Package Checklist | P20: =MPDD!B2 -> FALSE | Q20: Auto Calculated
N21: STD-008124 (-1)_2: The delivered MPDD has no proprietary labels applied to any of its pages. | O21: Mission Package Description Document (MPDD) | P21: AC 1-2 Met?
I22: STD-008124 (-2): This requirement is verified by inspection of the Mission Package Description Document (MPDD) showing that the access control implementation(s) for data transfer are documented. | J22: 1, 2, 3 | K22: The MPDD documents the “as built” cybersecurity implementation details. Each VR focuses on a different aspect of cybersecurity. This information is documented in the “Cybersecurity Access Controls” section of the MPDD. | L22: (-2)_1 (-2)_2 | M22: =IF(P22=TRUE,TRUE,(AND((OR(IF(P23=TRUE,TRUE,FALSE),(IF(P23="N/A",NOT(ISBLANK(Q23))))))))) -> FALSE | N22: STD-008124 (-2)_1: If access control for data transfer is not required, then this VR is satisfied. | O22: Mission Package Description Document (MPDD) | P22: AC 2-1 Met?
N23: STD-008124 (-2)_2: The MPDD documents the access control implementation(s) for data transfer for the Mission Package. | O23: Mission Package Description Document (MPDD) | P23: AC 2-2 Met?
I24: STD-008124 (-3): This requirement is verified by inspection of the Mission Package Description Document (MPDD) showing that the information flow control implementation(s) for data transfer are documented. | J24: 1, 2, 3 | K24: The MPDD documents the “as built” cybersecurity implementation details. Each VR focuses on a different aspect of cybersecurity. This information is documented in the “Cybersecurity Flow, Ports and Protocols Restriction Policy” section of the MPDD. | L24: (-3)_1 (-3)_2 | M24: =IF(P24=TRUE,TRUE,(AND((OR(IF(P25=TRUE,TRUE,FALSE),(IF(P25="N/A",NOT(ISBLANK(Q25))))))))) -> FALSE | N24: STD-008124 (-3)_1: If information flow control for data transfer is not required, then this VR is satisfied. | O24: Mission Package Description Document (MPDD) | P24: AC 3-1 Met?
N25: STD-008124 (-3)_2: The MPDD documents the information flow control implementation(s) for data transfer for the Mission Package. | O25: Mission Package Description Document (MPDD) | P25: AC 3-2 Met?
I26: STD-008124 (-4): This requirement is verified by inspection of the Mission Package Description Document (MPDD) showing that the ports and protocols used for data transfer are documented. | J26: 1, 2, 3 | K26: The MPDD documents the “as built” cybersecurity implementation details. Each VR focuses on a different aspect of cybersecurity. This information is documented in the “Cybersecurity Flow, Ports and Protocols Restriction Policy” section of the MPDD. | L26: (-4)_1 (-4)_2 | M26: =IF(P26=TRUE,TRUE,(AND((OR(IF(P27=TRUE,TRUE,FALSE),(IF(P27="N/A",NOT(ISBLANK(Q27))))))))) -> FALSE | N26: STD-008124 (-4)_1: If ports or protocols for data transfer are not required, then this VR is satisfied. | O26: Mission Package Description Document (MPDD) | P26: AC 4-1 Met?
N27: STD-008124 (-4)_2: The MPDD documents the ports and protocols used for data transfer for the Mission Package. | O27: Mission Package Description Document (MPDD) | P27: AC 4-2 Met?
I28: STD-008124 (-5): This requirement is verified by inspection of the Mission Package Description Document (MPDD) showing that that the mechanism for restricting the ports and protocols for data transfer is documented. | J28: 1, 2, 3 | K28: The MPDD documents the “as built” cybersecurity implementation details. Each VR focuses on a different aspect of cybersecurity. This information is documented in the “Cybersecurity Flow, Ports and Protocols Restriction Policy” section of the MPDD. | L28: (-5)_1 (-5)_2 | M28: =IF(P28=TRUE,TRUE,(AND((OR(IF(P29=TRUE,TRUE,FALSE),(IF(P29="N/A",NOT(ISBLANK(Q29))))))))) -> FALSE | N28: STD-008124 (-5)_1: If restricting ports or protocols for data transfer is not required, then this VR is satisfied. | O28: Mission Package Description Document (MPDD) | P28: AC 5-1 Met?
N29: STD-008124 (-5)_2: The MPDD documents the mechanism for restricting the ports and protocols for data transfer for the Mission Package. | O29: Mission Package Description Document (MPDD) | P29: AC 5-2 Met?
I30: STD-008124 (-6): This requirement is verified by inspection of the Mission Package Description Document (MPDD) showing that the identification and authentication implementation(s) for data transfer are documented. | J30: 1, 2, 3 | K30: The MPDD documents the “as built” cybersecurity implementation details. Each VR focuses on a different aspect of cybersecurity. This information is documented in the “Cybersecurity Identification & Authentication Implementation(s)” section of the MPDD. | L30: (-6)_1 (-6)_2 | M30: =IF(P30=TRUE,TRUE,(AND((OR(IF(P31=TRUE,TRUE,FALSE),(IF(P31="N/A",NOT(ISBLANK(Q31))))))))) -> FALSE | N30: STD-008124 (-6)_1: If identification and authentication for data transfer is not required, then this VR is satisfied. | O30: Mission Package Description Document (MPDD) | P30: AC 6-1 Met?
N31: STD-008124 (-6)_2: The MPDD documents the identification and authentication implementation(s) for data transfer for the Mission Package. | O31: Mission Package Description Document (MPDD) | P31: AC 6-2 Met?
I32: STD-008124 (-7): This requirement is verified by inspection of the Mission Package Description Document (MPDD) showing that the confidentiality implementation(s) for data transfer are documented. | J32: 1, 2, 3 | K32: The MPDD documents the “as built” cybersecurity implementation details. Each VR focuses on a different aspect of cybersecurity. This information is documented in the “Cybersecurity Confidentiality Implementation(s)” section of the MPDD. | L32: (-7)_1 (-7)_2 | M32: =IF(P32=TRUE,TRUE,(AND((OR(IF(P33=TRUE,TRUE,FALSE),(IF(P33="N/A",NOT(ISBLANK(Q33))))))))) -> FALSE | N32: STD-008124 (-7)_1: If confidentiality for data transfer is not required, then this VR is satisfied. | O32: Mission Package Description Document (MPDD) | P32: AC 7-1 Met?
N33: STD-008124 (-7)_2: The MPDD documents the confidentiality implementation(s) for data transfer for the Mission Package. | O33: Mission Package Description Document (MPDD) | P33: AC 7-2 Met?
I34: STD-008124 (-8): This requirement is verified by inspection of the Mission Package Description Document (MPDD) showing that the integrity implementation(s) for data transfer are documented. | J34: 1, 2, 3 | K34: The MPDD documents the “as built” cybersecurity implementation details. Each VR focuses on a different aspect of cybersecurity. This information is documented in the “Cybersecurity Integrity Implementation(s)” section of the MPDD | L34: (-8)_1 (-8)_2 | M34: =IF(P34=TRUE,TRUE,(AND((OR(IF(P35=TRUE,TRUE,FALSE),(IF(P35="N/A",NOT(ISBLANK(Q35))))))))) -> FALSE | N34: STD-008124 (-8)_1: If integrity for data transfer is not required, then this VR is satisfied. | O34: Mission Package Description Document (MPDD) | P34: AC 8-1 Met?
N35: STD-008124 (-8)_2: The MPDD documents the integrity implementation(s) for data transfer for the Mission Package. | O35: Mission Package Description Document (MPDD) | P35: AC 8-2 Met?
A36: STD-010180 Tier 1, 2, 3 | B36: RQMT STD-010180 [A Tier 1 OMS Mission Package shall document its cybersecurity posture in accordance with the OMS Mission Package Worksheet Template.] | C36: =AND((OR(IF(F36=TRUE,TRUE,FALSE),IF(F36="N/A",TRUE,FALSE))),H36=TRUE) -> FALSE | F36: N/A | G36: (-1) | H36: =AND(M36) -> FALSE | I36: STD-010180 (-1): This requirement is verified by inspection of the Mission Package Worksheet (MPW) is complete and complies with the current version of the MPW Template, OMSC-TMP-006, and identifies the CSRC assigned to the Mission Package. | J36: 1, 2, 3 | K36: The cybersecurity posture as defined by the CSRC and described by the CSAs denotes what an OMS Architecture Element achieves as one element within a cyber-contested environment. The MPW documents the CSRC, which is typically assigned by the program. If the Mission Package does not have a program-assigned Cybersecurity requirement, “N/A” is a valid assignment in the CSRC field. “Current Version” in this context refers to the version of the MPW Template specified in the OMS Standard against which compliance is being measured. | L36: (-1)_1 (-1)_2 | M36: =IF(P36=TRUE,TRUE,(AND((OR(IF(P37=TRUE,TRUE,FALSE),(IF(P37="N/A",NOT(ISBLANK(Q37))))))))) -> FALSE | N36: STD-010180 (-1)_1: If there is no program-assigned Cybersecurity requirement, this VR is satisfied. | O36: Mission Package Worksheet | P36: AC 1-1 Met?
N37: STD-010180 (-1)_2: The Mission Package cybersecurity posture is documented in the MPW. | O37: Mission Package Worksheet | P37: AC 1-2 Met?
A38: STD-009714 Tier 1, 2, 3 | B38: RQMT STD-009714 [A Tier 1 OMS Mission Package shall document its cybersecurity posture in accordance with the “Cybersecurity Posture” section in the OMS Mission Package Description Document Template.] | C38: =AND((OR(IF(F38=TRUE,TRUE,FALSE),IF(F38="N/A",TRUE,FALSE))),H38=TRUE) -> FALSE | F38: N/A | G38: (-1) | H38: =AND(M38) -> FALSE | I38: STD-009714 (-1): This requirement is verified by inspection of the Mission Package Description Document (MPDD) “Cybersecurity Posture” section showing that the Mission Package cybersecurity posture is documented. | J38: 1, 2, 3 | K38: The cybersecurity posture as defined by the CSRC and described by the CSAs denotes what an OMS Architecture Element achieves as one element within a cyber-contested environment. The “Cybersecurity Posture” section describes the implementation of the cybersecurity posture by OMS Architecture Element and provides additional, unclassified, and/or non-proprietary details relating to the security of the OMS Architecture Element. The provided OMSC-GDE-003, Cybersecurity Guide, defines the concepts, guidance, and information that OMS Adopting Programs and system designers will utilize to document the cybersecurity posture. | L38: (-1)_1 (-1)_2 | M38: =IF(P38=TRUE,TRUE,(AND((OR(IF(P39=TRUE,TRUE,FALSE),(IF(P39="N/A",NOT(ISBLANK(Q39))))))))) -> FALSE | N38: STD-009714 (-1)_1: If there is no program-assigned Cybersecurity requirement, this VR is satisfied. | O38: Mission Package Description Document (MPDD) | P38: AC 1-1 Met?
N39: STD-009714 (-1)_2: The Mission Package cybersecurity posture is documented in the MPDD “Cybersecurity Posture” section. | O39: Mission Package Description Document (MPDD) | P39: AC 1-2 Met?
A40: STD-008675 Tier 2, 3 | B40: RQMT STD-008675 [A Tier 2 OMS Mission Package shall meet Tier 1 Mission Package requirements.] | C40: =AND((OR(IF(F40=TRUE,TRUE,FALSE),IF(F40="N/A",TRUE,FALSE))),H40=TRUE) -> FALSE | E40: STD-000101 STD-000102 STD-000103 STD-000104 STD-005004 STD-008124 STD-009208 STD-009714 STD-009924 STD-010180 | F40: =AND(C2,C6,C10,C14,C16,C18,C20,C4,C38,C36) -> FALSE | G40: (-1) | H40: =AND(M40) -> FALSE | I40: STD-008675 (-1): This requirement is verified by the inspection of compliance artifacts showing the subordinate requirements for RQMT STD-008675 have been met. | J40: 2, 3 | K40: Tier 2 OMS Mission Packages must meet all Tier 1 OMS Mission Package requirements. | L40: (-1)_1 | M40: =AND(OR(IF(P40=TRUE,TRUE,FALSE),(IF(P40="N/A",NOT(ISBLANK(Q40)))))) -> FALSE | N40: STD-008675 (-1)_1: The [[Mission Package RQMT Checklist]] tab of the Mission Package Checklist shows that the subordinate requirements listed in the “Subordinate Requirements” column for RQMT STD-008675 have been met. | O40: Mission Package Checklist | P40: =F40 -> FALSE | Q40: Auto Calculated
...

Sheet MPDD
A2: Mission Package Description Document Compliant to OMSC-TMP-007, Revision I, dated 22 January 2026? | B2: =AND(TRUE,F5,F6,F7,F8,F9,F13,F14,F28,F64,F66,F68) -> FALSE
A4: Mission Package Description Document Template Item | B4: Compliance | C4: Per Template? | D4: N/A Rationale | E4: Compliance Met? | F4: Section Rollup | G4: Level | H4: Row
A5: <REQUIRED: Mission Package Description Document Title> | B5: Required | C5: <Select> | E5: =IF($B5="Required",OR($C5=TRUE,AND($C5="N/A",NOT(ISBLANK($D5)))),IF($B5="Optional",TRUE,IF($B5="Required if applicable",OR($C5=TRUE,AND($C5="N/A",NOT(ISBLANK($D5)))),OR($C5=TRUE,AND($C5="N/A",NOT(ISBLANK($D5))))))) -> FALSE | F5: =AND(E5) -> FALSE | G5: 1 | H5: 5
A6: <REQUIRED: Date as DD Month YYYY> | B6: Required | C6: <Select> | E6: =IF($B6="Required",OR($C6=TRUE,AND($C6="N/A",NOT(ISBLANK($D6)))),IF($B6="Optional",TRUE,IF($B6="Required if applicable",OR($C6=TRUE,AND($C6="N/A",NOT(ISBLANK($D6)))),OR($C6=TRUE,AND($C6="N/A",NOT(ISBLANK($D6))))))) -> FALSE | F6: =AND(E6) -> FALSE | G6: 1 | H6: 6
A7: <REQUIRED: Organization> | B7: Required | C7: <Select> | E7: =IF($B7="Required",OR($C7=TRUE,AND($C7="N/A",NOT(ISBLANK($D7)))),IF($B7="Optional",TRUE,IF($B7="Required if applicable",OR($C7=TRUE,AND($C7="N/A",NOT(ISBLANK($D7)))),OR($C7=TRUE,AND($C7="N/A",NOT(ISBLANK($D7))))))) -> FALSE | F7: =AND(E7) -> FALSE | G7: 1 | H7: 7
A8: Required statements (may be more restrictive): DISCLAIMER: The discussion of non-federal entities, methods, products, or services does not imply any endorsement by the United States Government, the Department of Defense, or the Department of the Air Force. Distribution Statement A. Approved for public release: distribution is unlimited. | B8: Required | C8: <Select> | E8: =IF($B8="Required",OR($C8=TRUE,AND($C8="N/A",NOT(ISBLANK($D8)))),IF($B8="Optional",TRUE,IF($B8="Required if applicable",OR($C8=TRUE,AND($C8="N/A",NOT(ISBLANK($D8)))),OR($C8=TRUE,AND($C8="N/A",NOT(ISBLANK($D8))))))) -> FALSE | F8: =AND(E8) -> FALSE | G8: 1 | H8: 8
A9: Abstract | B9: Required | C9: <Select> | E9: =IF($B9="Required",OR($C9=TRUE,AND($C9="N/A",NOT(ISBLANK($D9)))),IF($B9="Optional",TRUE,IF($B9="Required if applicable",OR($C9=TRUE,AND($C9="N/A",NOT(ISBLANK($D9)))),OR($C9=TRUE,AND($C9="N/A",NOT(ISBLANK($D9))))))) -> FALSE | F9: =AND(E9,F10,F11,F12) -> FALSE | G9: 1 | H9: 9
A10: Open Mission Systems (OMS) is a non-proprietary open architecture for integrating subsystems and services into mission packages. | B10: Required | C10: <Select> | E10: =IF($B10="Required",OR($C10=TRUE,AND($C10="N/A",NOT(ISBLANK($D10)))),IF($B10="Optional",TRUE,IF($B10="Required if applicable",OR($C10=TRUE,AND($C10="N/A",NOT(ISBLANK($D10)))),OR($C10=TRUE,AND($C10="N/A",NOT(ISBLANK($D10))))))) -> FALSE | F10: =AND(E10) -> FALSE | G10: 2 | H10: 10
A11: This Mission Package Description Document (MPDD) complies with the Mission Package Description Document (MPDD) Template, OMSC-TMP-007, Revision I, dated 22 January 2026. | B11: Required | C11: <Select> | E11: =IF($B11="Required",OR($C11=TRUE,AND($C11="N/A",NOT(ISBLANK($D11)))),IF($B11="Optional",TRUE,IF($B11="Required if applicable",OR($C11=TRUE,AND($C11="N/A",NOT(ISBLANK($D11)))),OR($C11=TRUE,AND($C11="N/A",NOT(ISBLANK($D11))))))) -> FALSE | F11: =AND(E11) -> FALSE | G11: 2 | H11: 11
A12: The template is prescribed by the OMS Standard Version 2.5, OMSC-STD-001, Revision M, dated 22 January 2026. | B12: Required | C12: <Select> | E12: =IF($B12="Required",OR($C12=TRUE,AND($C12="N/A",NOT(ISBLANK($D12)))),IF($B12="Optional",TRUE,IF($B12="Required if applicable",OR($C12=TRUE,AND($C12="N/A",NOT(ISBLANK($D12)))),OR($C12=TRUE,AND($C12="N/A",NOT(ISBLANK($D12))))))) -> FALSE | F12: =AND(E12) -> FALSE | G12: 2 | H12: 12
A13: Revision Record | B13: Required | C13: <Select> | E13: =IF($B13="Required",OR($C13=TRUE,AND($C13="N/A",NOT(ISBLANK($D13)))),IF($B13="Optional",TRUE,IF($B13="Required if applicable",OR($C13=TRUE,AND($C13="N/A",NOT(ISBLANK($D13)))),OR($C13=TRUE,AND($C13="N/A",NOT(ISBLANK($D13))))))) -> FALSE | F13: =AND(E13) -> FALSE | G13: 1 | H13: 13
A14: 1 Overview | B14: Required | C14: <Select> | E14: =IF($B14="Required",OR($C14=TRUE,AND($C14="N/A",NOT(ISBLANK($D14)))),IF($B14="Optional",TRUE,IF($B14="Required if applicable",OR($C14=TRUE,AND($C14="N/A",NOT(ISBLANK($D14)))),OR($C14=TRUE,AND($C14="N/A",NOT(ISBLANK($D14))))))) -> FALSE | F14: =AND(E14,F15,F16,F19,F22,F24,F26) -> FALSE | G14: 1 | H14: 14
A15: Proprietary Notice: This document contains only non-proprietary information. Referenced documents conform to the Proprietary Notice statement for each major sub section. References to external documents that provide for the data in this section (i.e., Section 1) refer only to non-proprietary documents. | B15: Required | C15: <Select> | E15: =IF($B15="Required",OR($C15=TRUE,AND($C15="N/A",NOT(ISBLANK($D15)))),IF($B15="Optional",TRUE,IF($B15="Required if applicable",OR($C15=TRUE,AND($C15="N/A",NOT(ISBLANK($D15)))),OR($C15=TRUE,AND($C15="N/A",NOT(ISBLANK($D15))))))) -> FALSE | F15: =AND(E15) -> FALSE | G15: 2 | H15: 15
A16: 1.1 References | B16: Required | C16: <Select> | E16: =IF($B16="Required",OR($C16=TRUE,AND($C16="N/A",NOT(ISBLANK($D16)))),IF($B16="Optional",TRUE,IF($B16="Required if applicable",OR($C16=TRUE,AND($C16="N/A",NOT(ISBLANK($D16)))),OR($C16=TRUE,AND($C16="N/A",NOT(ISBLANK($D16))))))) -> FALSE | F16: =AND(E16,F17,F18) -> FALSE | G16: 2 | H16: 16
A17: Proprietary Notice: References to external documents that provide for the data in this section may refer to proprietary documents. | B17: Required | C17: <Select> | E17: =IF($B17="Required",OR($C17=TRUE,AND($C17="N/A",NOT(ISBLANK($D17)))),IF($B17="Optional",TRUE,IF($B17="Required if applicable",OR($C17=TRUE,AND($C17="N/A",NOT(ISBLANK($D17)))),OR($C17=TRUE,AND($C17="N/A",NOT(ISBLANK($D17))))))) -> FALSE | F17: =AND(E17) -> FALSE | G17: 3 | H17: 17
A18: Table 1.1-1 Reference Documents | B18: Required | C18: <Select> | E18: =IF($B18="Required",OR($C18=TRUE,AND($C18="N/A",NOT(ISBLANK($D18)))),IF($B18="Optional",TRUE,IF($B18="Required if applicable",OR($C18=TRUE,AND($C18="N/A",NOT(ISBLANK($D18)))),OR($C18=TRUE,AND($C18="N/A",NOT(ISBLANK($D18))))))) -> FALSE | F18: =AND(E18) -> FALSE | G18: 3 | H18: 18
A19: 1.2 Mission Package Worksheet | B19: Required | C19: <Select> | E19: =IF($B19="Required",OR($C19=TRUE,AND($C19="N/A",NOT(ISBLANK($D19)))),IF($B19="Optional",TRUE,IF($B19="Required if applicable",OR($C19=TRUE,AND($C19="N/A",NOT(ISBLANK($D19)))),OR($C19=TRUE,AND($C19="N/A",NOT(ISBLANK($D19))))))) -> FALSE | F19: =AND(E19,F20,F21) -> FALSE | G19: 2 | H19: 19
A20: Table 1.2-1 Mission Package Worksheet | B20: Required | C20: <Select> | E20: =IF($B20="Required",OR($C20=TRUE,AND($C20="N/A",NOT(ISBLANK($D20)))),IF($B20="Optional",TRUE,IF($B20="Required if applicable",OR($C20=TRUE,AND($C20="N/A",NOT(ISBLANK($D20)))),OR($C20=TRUE,AND($C20="N/A",NOT(ISBLANK($D20))))))) -> FALSE | F20: =AND(E20) -> FALSE | G20: 3 | H20: 20
A21: Table 1.2-2 Units of Replaceability Within the Mission Package Worksheet | B21: Required | C21: <Select> | E21: =IF($B21="Required",OR($C21=TRUE,AND($C21="N/A",NOT(ISBLANK($D21)))),IF($B21="Optional",TRUE,IF($B21="Required if applicable",OR($C21=TRUE,AND($C21="N/A",NOT(ISBLANK($D21)))),OR($C21=TRUE,AND($C21="N/A",NOT(ISBLANK($D21))))))) -> FALSE | F21: =AND(E21) -> FALSE | G21: 3 | H21: 21
A22: 1.3 Mission Package Data Storage | B22: Required | C22: <Select> | E22: =IF($B22="Required",OR($C22=TRUE,AND($C22="N/A",NOT(ISBLANK($D22)))),IF($B22="Optional",TRUE,IF($B22="Required if applicable",OR($C22=TRUE,AND($C22="N/A",NOT(ISBLANK($D22)))),OR($C22=TRUE,AND($C22="N/A",NOT(ISBLANK($D22))))))) -> FALSE | F22: =AND(E22,F23) -> FALSE | G22: 2 | H22: 22
A23: Table 1.3-1 Data Storage Allocation | B23: Required | C23: <Select> | E23: =IF($B23="Required",OR($C23=TRUE,AND($C23="N/A",NOT(ISBLANK($D23)))),IF($B23="Optional",TRUE,IF($B23="Required if applicable",OR($C23=TRUE,AND($C23="N/A",NOT(ISBLANK($D23)))),OR($C23=TRUE,AND($C23="N/A",NOT(ISBLANK($D23))))))) -> FALSE | F23: =AND(E23) -> FALSE | G23: 3 | H23: 23
A24: 1.4 Mission Package Open Computing Environment (OCE) | B24: Required | C24: <Select> | E24: =IF($B24="Required",OR($C24=TRUE,AND($C24="N/A",NOT(ISBLANK($D24)))),IF($B24="Optional",TRUE,IF($B24="Required if applicable",OR($C24=TRUE,AND($C24="N/A",NOT(ISBLANK($D24)))),OR($C24=TRUE,AND($C24="N/A",NOT(ISBLANK($D24))))))) -> FALSE | F24: =AND(E24,F25) -> FALSE | G24: 2 | H24: 24
A25: Table 1.4-1 Open Computing Environment | B25: Required | C25: <Select> | E25: =IF($B25="Required",OR($C25=TRUE,AND($C25="N/A",NOT(ISBLANK($D25)))),IF($B25="Optional",TRUE,IF($B25="Required if applicable",OR($C25=TRUE,AND($C25="N/A",NOT(ISBLANK($D25)))),OR($C25=TRUE,AND($C25="N/A",NOT(ISBLANK($D25))))))) -> FALSE | F25: =AND(E25) -> FALSE | G25: 3 | H25: 25
A26: 1.5 Mission Package External Interface | B26: Required | C26: <Select> | E26: =IF($B26="Required",OR($C26=TRUE,AND($C26="N/A",NOT(ISBLANK($D26)))),IF($B26="Optional",TRUE,IF($B26="Required if applicable",OR($C26=TRUE,AND($C26="N/A",NOT(ISBLANK($D26)))),OR($C26=TRUE,AND($C26="N/A",NOT(ISBLANK($D26))))))) -> FALSE | F26: =AND(E26,F27) -> FALSE | G26: 2 | H26: 26
A27: Table 1.5-1 External Interface | B27: Required | C27: <Select> | E27: =IF($B27="Required",OR($C27=TRUE,AND($C27="N/A",NOT(ISBLANK($D27)))),IF($B27="Optional",TRUE,IF($B27="Required if applicable",OR($C27=TRUE,AND($C27="N/A",NOT(ISBLANK($D27)))),OR($C27=TRUE,AND($C27="N/A",NOT(ISBLANK($D27))))))) -> FALSE | F27: =AND(E27) -> FALSE | G27: 3 | H27: 27
A28: 2 Cybersecurity Posture | B28: Required | C28: <Select> | E28: =IF($B28="Required",OR($C28=TRUE,AND($C28="N/A",NOT(ISBLANK($D28)))),IF($B28="Optional",TRUE,IF($B28="Required if applicable",OR($C28=TRUE,AND($C28="N/A",NOT(ISBLANK($D28)))),OR($C28=TRUE,AND($C28="N/A",NOT(ISBLANK($D28))))))) -> FALSE | F28: =AND(E28,F29,F30,F32,F34,F63) -> FALSE | G28: 1 | H28: 28
A29: Proprietary Notice: References to external documents that provide for the data in this section refer only to non-proprietary documents. | B29: Required | C29: <Select> | E29: =IF($B29="Required",OR($C29=TRUE,AND($C29="N/A",NOT(ISBLANK($D29)))),IF($B29="Optional",TRUE,IF($B29="Required if applicable",OR($C29=TRUE,AND($C29="N/A",NOT(ISBLANK($D29)))),OR($C29=TRUE,AND($C29="N/A",NOT(ISBLANK($D29))))))) -> FALSE | F29: =AND(E29) -> FALSE | G29: 2 | H29: 29
A30: 2.1 Policy Overview | B30: Required | C30: <Select> | E30: =IF($B30="Required",OR($C30=TRUE,AND($C30="N/A",NOT(ISBLANK($D30)))),IF($B30="Optional",TRUE,IF($B30="Required if applicable",OR($C30=TRUE,AND($C30="N/A",NOT(ISBLANK($D30)))),OR($C30=TRUE,AND($C30="N/A",NOT(ISBLANK($D30))))))) -> FALSE | F30: =AND(E30,F31) -> FALSE | G30: 2 | H30: 30
A31: Figure 2.1-1 OMS Cybersecurity Guidance in Acquisition | B31: Required | C31: <Select> | E31: =IF($B31="Required",OR($C31=TRUE,AND($C31="N/A",NOT(ISBLANK($D31)))),IF($B31="Optional",TRUE,IF($B31="Required if applicable",OR($C31=TRUE,AND($C31="N/A",NOT(ISBLANK($D31)))),OR($C31=TRUE,AND($C31="N/A",NOT(ISBLANK($D31))))))) -> FALSE | F31: =AND(E31) -> FALSE | G31: 3 | H31: 31
A32: 2.2 CSRC | B32: Required | C32: <Select> | E32: =IF($B32="Required",OR($C32=TRUE,AND($C32="N/A",NOT(ISBLANK($D32)))),IF($B32="Optional",TRUE,IF($B32="Required if applicable",OR($C32=TRUE,AND($C32="N/A",NOT(ISBLANK($D32)))),OR($C32=TRUE,AND($C32="N/A",NOT(ISBLANK($D32))))))) -> FALSE | F32: =AND(E32,F33) -> FALSE | G32: 2 | H32: 32
A33: Table 2.2-1 Mission Package CSRC | B33: Required | C33: <Select> | E33: =IF($B33="Required",OR($C33=TRUE,AND($C33="N/A",NOT(ISBLANK($D33)))),IF($B33="Optional",TRUE,IF($B33="Required if applicable",OR($C33=TRUE,AND($C33="N/A",NOT(ISBLANK($D33)))),OR($C33=TRUE,AND($C33="N/A",NOT(ISBLANK($D33))))))) -> FALSE | F33: =AND(E33) -> FALSE | G33: 3 | H33: 33
A34: 2.3 Cyber Survivability Attributes (CSAs) | B34: Required | C34: <Select> | E34: =IF($B34="Required",OR($C34=TRUE,AND($C34="N/A",NOT(ISBLANK($D34)))),IF($B34="Optional",TRUE,IF($B34="Required if applicable",OR($C34=TRUE,AND($C34="N/A",NOT(ISBLANK($D34)))),OR($C34=TRUE,AND($C34="N/A",NOT(ISBLANK($D34))))))) -> FALSE | F34: =AND(E34,F35,F59,F61,F62) -> FALSE | G34: 2 | H34: 34
A35: 2.3.1 Prevent CSAs | B35: Required | C35: <Select> | E35: =IF($B35="Required",OR($C35=TRUE,AND($C35="N/A",NOT(ISBLANK($D35)))),IF($B35="Optional",TRUE,IF($B35="Required if applicable",OR($C35=TRUE,AND($C35="N/A",NOT(ISBLANK($D35)))),OR($C35=TRUE,AND($C35="N/A",NOT(ISBLANK($D35))))))) -> FALSE | F35: =AND(E35,F36,F37,F39,F44,F46,F50,F52,F57) -> FALSE | G35: 3 | H35: 35
A36: Table 2.3-1 Applicable System Survivability KPP Prevent CSAs | B36: Required | C36: <Select> | E36: =IF($B36="Required",OR($C36=TRUE,AND($C36="N/A",NOT(ISBLANK($D36)))),IF($B36="Optional",TRUE,IF($B36="Required if applicable",OR($C36=TRUE,AND($C36="N/A",NOT(ISBLANK($D36)))),OR($C36=TRUE,AND($C36="N/A",NOT(ISBLANK($D36))))))) -> FALSE | F36: =AND(E36) -> FALSE | G36: 4 | H36: 36
A37: 2.3.1.1 Security Domain Definition | B37: Required | C37: <Select> | E37: =IF($B37="Required",OR($C37=TRUE,AND($C37="N/A",NOT(ISBLANK($D37)))),IF($B37="Optional",TRUE,IF($B37="Required if applicable",OR($C37=TRUE,AND($C37="N/A",NOT(ISBLANK($D37)))),OR($C37=TRUE,AND($C37="N/A",NOT(ISBLANK($D37))))))) -> FALSE | F37: =AND(E37,F38) -> FALSE | G37: 4 | H37: 37
A38: Figure 2.3-1 Security Domain Boundaries | B38: Required | C38: <Select> | E38: =IF($B38="Required",OR($C38=TRUE,AND($C38="N/A",NOT(ISBLANK($D38)))),IF($B38="Optional",TRUE,IF($B38="Required if applicable",OR($C38=TRUE,AND($C38="N/A",NOT(ISBLANK($D38)))),OR($C38=TRUE,AND($C38="N/A",NOT(ISBLANK($D38))))))) -> FALSE | F38: =AND(E38) -> FALSE | G38: 5 | H38: 38
A39: 2.3.1.2 Cybersecurity Flow Description | B39: Required | C39: <Select> | E39: =IF($B39="Required",OR($C39=TRUE,AND($C39="N/A",NOT(ISBLANK($D39)))),IF($B39="Optional",TRUE,IF($B39="Required if applicable",OR($C39=TRUE,AND($C39="N/A",NOT(ISBLANK($D39)))),OR($C39=TRUE,AND($C39="N/A",NOT(ISBLANK($D39))))))) -> FALSE | F39: =AND(E39,F40,F41,F42,F43) -> FALSE | G39: 4 | H39: 39
A40: Figure 2.3-2 Non-Streaming Data Transfer Information Flow Diagram | B40: Required | C40: <Select> | E40: =IF($B40="Required",OR($C40=TRUE,AND($C40="N/A",NOT(ISBLANK($D40)))),IF($B40="Optional",TRUE,IF($B40="Required if applicable",OR($C40=TRUE,AND($C40="N/A",NOT(ISBLANK($D40)))),OR($C40=TRUE,AND($C40="N/A",NOT(ISBLANK($D40))))))) -> FALSE | F40: =AND(E40) -> FALSE | G40: 5 | H40: 40
A41: Table 2.3-2 Non-Streaming Data Transfer Information Flow | B41: Required | C41: <Select> | E41: =IF($B41="Required",OR($C41=TRUE,AND($C41="N/A",NOT(ISBLANK($D41)))),IF($B41="Optional",TRUE,IF($B41="Required if applicable",OR($C41=TRUE,AND($C41="N/A",NOT(ISBLANK($D41)))),OR($C41=TRUE,AND($C41="N/A",NOT(ISBLANK($D41))))))) -> FALSE | F41: =AND(E41) -> FALSE | G41: 5 | H41: 41
A42: Figure 2.3-3 Streaming Data Transfer Information Flow Diagram | B42: Required | C42: <Select> | E42: =IF($B42="Required",OR($C42=TRUE,AND($C42="N/A",NOT(ISBLANK($D42)))),IF($B42="Optional",TRUE,IF($B42="Required if applicable",OR($C42=TRUE,AND($C42="N/A",NOT(ISBLANK($D42)))),OR($C42=TRUE,AND($C42="N/A",NOT(ISBLANK($D42))))))) -> FALSE | F42: =AND(E42) -> FALSE | G42: 5 | H42: 42
...
