Workbook

Sheet WARNING NOTE
A6: WARNING NOTICE
A8: THIS CHECKLIST HAS FORMULAS THAT AUTOMATICALLY CALCULATE SUMMATIONS AND ROLL-UPS OF COMPLIANCE STATE. THESE FORMULAS MAY HAVE ERRORS THAT HAVE NOT BEEN DETECTED. PLEASE BE ADVISED THAT DUE TO THE POTENTIAL FOR AN ERROR IT IS RECOMMENDED THAT A MANUAL VERIFICATION BE PERFORMED BY THE PERSON OR ORGANIZATION FILLING OUT THE CHECKLIST TO ENSURE THAT THE CHECKLIST ACCURATELY REFLECTS THE STATE OF COMPLIANCE FOR THE OMS ELEMENT IN QUESTION.
A10: Notes for the User:
A12: This workbook has protection applied to preserve formulas and cross referencing.
A14: User input is only required/allowed in the blue shaded cells of each worksheet, except for the Cover, Abstract and Rev Table, which are user editable.

Sheet Cover
A3: <REQUIRED: PLATFORM CHECKLIST TITLE>
A4: <OPTIONAL: Organization CDRL Number>
A5: <OPTIONAL: Organization Logo>
A6: Prepared By:
A7: <REQUIRED: Organization>
A8: <OPTIONAL: Address>
A10: DISCLAIMER: The discussion of non-federal entities, methods, products, or services does not imply any endorsement by the United States Government, the Department of Defense, or the Department of the Air Force.
A11: Distribution Statement A. Approved for public release: distribution is unlimited.

Sheet Abstract
A1: ABSTRACT
A2: < The abstract is REQUIRED and is a brief summary of the document that follows and is used to help the reader quickly ascertain the document's purpose and overall content. >
A3: < Before attempting to fill out this checklist, the Platform compliance assessor should have access to the referenced Platform Description Document (PDD) for the Platform. >
A4: This Platform Checklist complies with the OMS Standard Version 2.5, OMSC-STD-001, Revision M, 22 January 2026.

Sheet Rev
A2: REVISION RECORD
A4: REVISION | B4: DATE | C4: DESCRIPTION
A5: - | B5: dd-mmm-yy | C5: Original

Sheet Tier Compliance
A1: Tier Compliance at: | B1: =IF(E54=TRUE,"Tier 3", IF(E47=TRUE,"Tier 2",IF(G31=TRUE,"Tier 1", "Not Tier Compliant"))) -> Not Tier Compliant
A3: Platform Tier 1 RQMTS
A4: RQMT ID | B4: RQMT Topic | C4: Subordinate RQMTs | D4: Subordinate RQMTs Topic | E4: Subordinate RQMTs | F4: Subordinate RQMTs Topic | G4: RQMT Met?
A5: STD-000082 Tier 1, 2, 3 | B5: Provide OMS ASB | C5: list below | D5: list below | E5: list below | F5: list below | G5: ='Platform RQMT Checklist'!C28 -> FALSE
C6: STD-000144 Tier 1, 2, 3 | D6: Support IPv4 or IPv6 | E6: N/A | F6: N/A | G6: ='Platform RQMT Checklist'!C2 -> FALSE
C7: STD-000146 Tier 1, 2, 3 | D7: Provide OMS CAL | E7: list below | F7: list below | G7: ='Platform RQMT Checklist'!C3 -> FALSE
E8: STD-000190 Tier 1, 2, 3 | F8: Develop CAL Implementation | G8: ='Platform RQMT Checklist'!C5 -> FALSE
C9: STD-009706 Tier 1, 2, 3 | D9: Provide OMS Security Information Exchange | E9: N/A | F9: N/A | G9: ='Platform RQMT Checklist'!C4 -> FALSE
A10: STD-000083 Tier 1, 2, 3 | B10: Provide OMS OCE | C10: list below | D10: list below | E10: list below | F10: list below | G10: ='Platform RQMT Checklist'!C29 -> FALSE
C11: STD-000350 Tier 1, 2, 3 | D11: Host C++ OMS CAL | E11: N/A | F11: N/A | G11: ='Platform RQMT Checklist'!C12 -> FALSE
C12: STD-000351 Tier 1, 2, 3 | D12: Host Java OMS CAL | E12: N/A | F12: N/A | G12: ='Platform RQMT Checklist'!C13 -> FALSE
C13: STD-000352 Tier 1, 2, 3 | D13: OCE Hosted Service | E13: N/A | F13: N/A | G13: ='Platform RQMT Checklist'!C15 -> FALSE
C14: STD-000354 Tier 1, 2, 3 | D14: Synchronize System Clock | E14: N/A | F14: N/A | G14: ='Platform RQMT Checklist'!C16 -> FALSE
C15: STD-000355 Tier 1, 2, 3 | D15: Provide Time | E15: N/A | F15: N/A | G15: ='Platform RQMT Checklist'!C17 -> FALSE
C16: STD-000360 Tier 1, 2, 3 | D16: Provide Linux OS | E16: N/A | F16: N/A | G16: ='Platform RQMT Checklist'!C18 -> FALSE
C17: STD-000362 Tier 1, 2, 3 | D17: Provide 64 bit Linux OS | E17: N/A | F17: N/A | G17: ='Platform RQMT Checklist'!C19 -> FALSE
C18: STD-000365 Tier 1, 2, 3 | D18: Provide Façade Implementation | E18: list below | F18: list below | G18: ='Platform RQMT Checklist'!C21 -> FALSE
E19: STD-000381 Tier 1, 2, 3 | F19: Provide OMS Façade API | G19: ='Platform RQMT Checklist'!C24 -> FALSE
C20: STD-008663 Tier 1, 2, 3 | D20: Provide Java Implementation | E20: list below | F20: list below | G20: ='Platform RQMT Checklist'!C22 -> FALSE
E21: STD-000385 Tier 1, 2, 3 | F21: Provide JRE | G21: ='Platform RQMT Checklist'!C25 -> FALSE
A22: STD-000085 Tier 1, 2, 3 | B22: Platform Description Document (PDD) Required | C22: N/A | D22: N/A | E22: N/A | F22: N/A | G22: ='Platform RQMT Checklist'!C30 -> FALSE
A23: STD-000086 Tier 1, 2, 3 | B23: Provision for Special Signals | C23: N/A | D23: N/A | E23: N/A | F23: N/A | G23: ='Platform RQMT Checklist'!C50 -> FALSE
A24: STD-005002 Tier 1, 2, 3 | B24: Provide Internet Protocol (IP) | C24: N/A | D24: N/A | E24: N/A | F24: N/A | G24: ='Platform RQMT Checklist'!C52 -> FALSE
A25: STD-000303 Tier 1, 2, 3 | B25: Provide Time Synchronization | C25: N/A | D25: N/A | E25: N/A | F25: N/A | G25: ='Platform RQMT Checklist'!C53 -> FALSE
A26: STD-000307 Tier 1, 2, 3 | B26: Time Synchronization | C26: N/A | D26: N/A | E26: N/A | F26: N/A | G26: ='Platform RQMT Checklist'!C54 -> FALSE
A27: STD-000314 Tier 1, 2, 3 | B27: High Fidelity Time Synchronization | C27: N/A | D27: N/A | E27: N/A | F27: N/A | G27: ='Platform RQMT Checklist'!C55 -> FALSE
A28: STD-000325 Tier 1, 2, 3 | B28: Provide Platform Position | C28: N/A | D28: N/A | E28: N/A | F28: N/A | G28: ='Platform RQMT Checklist'!C57 -> FALSE
A29: STD-000334 Tier 1, 2, 3 | B29: High Fidelity Navigation | C29: N/A | D29: N/A | E29: N/A | F29: N/A | G29: ='Platform RQMT Checklist'!C69 -> FALSE
A30: STD-009712 Tier 1, 2, 3 | B30: Document Cybersecurity posture | C30: N/A | D30: N/A | E30: N/A | F30: N/A | G30: ='Platform RQMT Checklist'!C81 -> FALSE
F31: Tier 1 RQMTs Met? | G31: =AND(G5:G30) -> FALSE
A33: Platform Tier 2 RQMTS
A34: RQMT ID | B34: RQMT Topic | C34: Subordinate RQMTs | D34: Subordinate RQMTs Topic | E34: RQMT Met?
A35: STD-000088 Tier 2, 3 | B35: Meet All Tier 1 Requirements | C35: list below | D35: list below | E35: ='Platform RQMT Checklist'!C83 -> FALSE
C36: STD-000082 Tier 1, 2, 3 | D36: Provide OMS ASB | E36: ='Platform RQMT Checklist'!C28 -> FALSE
C37: STD-000083 Tier 1, 2, 3 | D37: Provide OMS OCE | E37: ='Platform RQMT Checklist'!C29 -> FALSE
C38: STD-000085 Tier 1, 2, 3 | D38: Platform Description Document (PDD) Required | E38: ='Platform RQMT Checklist'!C30 -> FALSE
C39: STD-000086 Tier 1, 2, 3 | D39: Provision for Special Signals | E39: ='Platform RQMT Checklist'!C50 -> FALSE
C40: STD-000303 Tier 1, 2, 3 | D40: Provide Time Synchronization | E40: ='Platform RQMT Checklist'!C53 -> FALSE
C41: STD-000307 Tier 1, 2, 3 | D41: Time Synchronization | E41: ='Platform RQMT Checklist'!C54 -> FALSE
C42: STD-000314 Tier 1, 2, 3 | D42: High Fidelity Time Synchronization | E42: ='Platform RQMT Checklist'!C55 -> FALSE
...

Sheet Platform RQMT Checklist
A1: RQMT ID | B1: RQMT Text | C1: RQMT Met? | D1: Clarification | E1: Subordinate RQMTS | F1: Sub RQMTS Met? | G1: VR List | H1: All VRs Met? | I1: Verification Requirement (VR) | J1: VR Tier | K1: Guidance | L1: AC List | M1: VR Met? | N1: Acceptance Criteria (AC) | O1: Assessed Article | P1: AC Met? | Q1: N/A Rationale
A2: STD-000144 Tier 1, 2, 3 | B2: RQMT STD-000144 [An OMS ASB shall support Internet Protocols IPv4 or IPv6.] | C2: =AND((OR(IF(F2=TRUE,TRUE,FALSE),IF(F2="N/A",TRUE,FALSE))),H2=TRUE) -> FALSE | F2: N/A | G2: (-1) | H2: =AND(M2) -> FALSE | I2: STD-000144 (-1): This requirement is verified by inspection of the Platform Description Document (PDD) showing that data exchanges using either IPv4 or IPv6 protocols are supported. | J2: 1, 2, 3 | K2: This requirement is intended to show that UDP and TCP packet transfers over an IP network are fully supported by the ASB; this information is included in the “Abstract Service Bus” section of the PDD. | L2: (-1)_1 | M2: =AND(OR(IF(P2=TRUE,TRUE,FALSE),(IF(P2="N/A",NOT(ISBLANK(Q2)))))) -> FALSE | N2: STD-000144 (-1)_1: The PDD documents that the transmission of data packets over either an IPv4 or IPv6 network is supported by the ASB. | O2: Platform Description Document (PDD) | P2: AC 1-1 Met?
A3: STD-000146 Tier 1, 2, 3 | B3: RQMT STD-000146 [An OMS ASB shall provide the OMS CAL.] | C3: =AND((OR(IF(F3=TRUE,TRUE,FALSE),IF(F3="N/A",TRUE,FALSE))),H3=TRUE) -> FALSE | E3: STD-000190 | F3: =AND(C5) -> FALSE | G3: (-1) | H3: =AND(M3) -> FALSE | I3: STD-000146 (-1): This requirement is verified by the inspection of the [[Platform RQMT Checklist]] tab of the Platform Checklist, OMSC-CHK-003, that shows the subordinate requirements for RQMT STD-000146 have been met. | J3: 1, 2, 3 | K3: The OCE should have C++ and Java CAL implementations and optionally Language-Agnostic CAL implementations. Each distinct implementation of the CAL should meet this RQMT. If Java is prohibited due to system security policy, then only a C++ CAL implementation would be required for the OCE. The OMS Platform should provide Other Mission Processing elements in addition to those that host the OCE. | L3: (-1)_1 | M3: =AND(OR(IF(P3=TRUE,TRUE,FALSE),(IF(P3="N/A",NOT(ISBLANK(Q3)))))) -> FALSE | N3: STD-000146 (-1)_1: The [[Platform RQMT Checklist]] tab of the Platform Checklist shows that the subordinate requirements listed in the “Subordinate Requirements” column for RQMT STD-000146 have been met for each applicable CAL implementation. | O3: Platform Checklist | P3: =F3 -> FALSE | Q3: Auto Calculated
A4: STD-009706 Tier 1, 2, 3 | B4: RQMT STD-009706 [An OMS ASB shall provide OMS Security Information Exchanges.] | C4: =AND((OR(IF(F4=TRUE,TRUE,FALSE),IF(F4="N/A",TRUE,FALSE))),H4=TRUE) -> FALSE | F4: N/A | G4: (-1) | H4: =AND(M4) -> FALSE | I4: STD-009706 (-1): This requirement is verified by inspection of the Platform Description Document (PDD) showing that the OMS ASB is capable of transmitting the OMS security information exchanges in accordance with the “Security Information Exchanges” section. | J4: 1, 2, 3 | K4: This information is documented in the Security Addendum for the PDD. The Security Addendum is identified in the “Security Addendum” section of the PDD. | L4: (-1)_1 | M4: =AND(OR(IF(P4=TRUE,TRUE,FALSE),(IF(P4="N/A",NOT(ISBLANK(Q4)))))) -> FALSE | N4: STD-009706 (-1)_1: The PDD, or the PDD Security Addendum, identifies the means for transmitting the OMS security information exchanges in accordance with the “Security Information Exchanges” section. | O4: Platform Description Document (PDD) | P4: AC 1-1 Met?
A5: STD-000190 Tier 1, 2, 3 | B5: RQMT STD-000190 [An OMS CAL implementation shall be developed.] | C5: =AND((OR(IF(F5=TRUE,TRUE,FALSE),IF(F5="N/A",TRUE,FALSE))),H5=TRUE) -> FALSE | F5: N/A | G5: (-1) (-2) (-3) (-4) | H5: =AND(M5,M6,M8,M10) -> FALSE | I5: STD-000190 (-1): This requirement is verified by inspection of the Platform Description Document (PDD) showing that a language-specific CAL implementation has been developed. | J5: 1, 2, 3 | K5: Each distinct language-specific CAL implementation, C++ and Java, must adhere to the CAL Specification. If an OMS Platform has additional mission processing elements outside of the OCE, then those additional CAL implementations will need to adhere as well. This requirement may be satisfied by using the CAL Schema Compiler tool to generate the CAL API. | L5: (-1)_1 (-1)_2 | M5: =AND(OR(IF(P5=TRUE,TRUE,FALSE),(IF(P5="N/A",NOT(ISBLANK(Q5)))))) -> FALSE | N5: STD-000190 (-1)_1: The PDD documents that a language-specific CAL implementation has been developed. | O5: Platform Description Document (PDD) | P5: AC 1-1 Met?
I6: STD-000190 (-2): This requirement is verified by inspection of the CAL-VTS test results documenting the successful demonstration of the applicable language-specific CAL API and any requirement that is untestable by CAL-VTS is verified by inspection of the Platform Description Document (PDD) showing that the generated CAL API has been shown to be equivalent to the API generated by the CAL Schema Compiler. | J6: 1, 2, 3 | K6: Each distinct language-specific CAL implementation, C++ and Java, must adhere to the CAL Specification. If an OMS Platform has additional mission processing elements outside of the OCE, then those additional CAL implementations will need to adhere as well. This requirement may be satisfied by using CAL-VTS to evaluate the API. In the context of this VR equivalence is defined as follows: A generated CAL API is “equivalent” to the API generated by the Schema Compiler if a Service that compiles against the Schema Compiler output API compiles against the generated CAL API with no change. | L6: (-2)_1 (-2)_2 | M6: =IF(P6=TRUE,TRUE,(AND((OR(IF(P7=TRUE,TRUE,FALSE),(IF(P7="N/A",NOT(ISBLANK(Q7))))))))) -> FALSE | N6: STD-000190 (-2)_1: If all applicable language-specific CAL Specification CERTs are tested successfully by CAL-VTS, then this VR is satisfied. | O6: Platform Description Document (PDD) | P6: AC 2-1 Met?
N7: STD-000190 (-2)_2: The PDD documents that the generated language-specific CAL API is equivalent with the API generated by the CAL Schema Compiler tool associated with the appropriate programming language interface generation specification. | O7: Platform Description Document (PDD) | P7: AC 2-2 Met?
I8: STD-000190 (-3): This requirement is verified by inspection of the Platform Description Document (PDD) showing that provided language-agnostic CAL implementations have been developed. | J8: 1, 2, 3 | K8: Each distinct language-agnostic CAL implementation must adhere to the Language-Agnostic CAL Specification. A language-agnostic CAL implementation is not required; however, a Platform may choose to provide one or more implementations. All information needed to interact with each provided language-agnostic CAL implementation is provided in the PDD. | L8: (-3)_1 (-3)_2 | M8: =IF(P8=TRUE,TRUE,(AND((OR(IF(P9=TRUE,TRUE,FALSE),(IF(P9="N/A",NOT(ISBLANK(Q9))))))))) -> FALSE | N8: STD-000190 (-3)_1: If a language-agnostic CAL implementation is not provided, then this VR is satisfied. | O8: Platform Description Document (PDD) | P8: AC 3-1 Met?
N9: STD-000190 (-3)_2: The PDD documents that provided language-agnostic CAL implementations have been developed. | O9: Platform Description Document (PDD) | P9: AC 3-2 Met?
I10: STD-000190 (-4): This requirement is verified by inspection of the functional test results documenting the provided language-agnostic CAL implementation(s) adhere to the Language-Agnostic CAL Specification. | J10: 1, 2, 3 | K10: Each distinct language-agnostic CAL implementation must adhere to the Language-Agnostic CAL Specification. A language-agnostic CAL implementation is not required; however, a Platform may choose to provide one or more implementations. All information needed to interact with each provided language-agnostic CAL implementation is provided in the PDD. For each language-agnostic CAL implementation, functional test results show the language-agnostic CAL’s API has been implemented. | L10: (-4)_1 (-4)_2 | M10: =IF(P10=TRUE,TRUE,(AND((OR(IF(P11=TRUE,TRUE,FALSE),(IF(P11="N/A",NOT(ISBLANK(Q11))))))))) -> FALSE | N10: STD-000190 (-4)_1: If a language-agnostic CAL implementation is not provided, then this VR is satisfied. | O10: functional test results | P10: AC 4-1 Met?
N11: STD-000190 (-4)_2: The PDD documents the functional test results indicating provided language-agnostic CAL implementations adhere to the Language-Agnostic CAL Specification. | O11: functional test results | P11: AC 4-2 Met?
A12: STD-000350 Tier 1, 2, 3 | B12: RQMT STD-000350 [An OMS OCE shall host a C++ OMS CAL implementation.] | C12: =AND((OR(IF(F12=TRUE,TRUE,FALSE),IF(F12="N/A",TRUE,FALSE))),H12=TRUE) -> FALSE | F12: N/A | G12: (-1) | H12: =AND(M12) -> FALSE | I12: STD-000350 (-1): This requirement is verified by inspection of the functional test results documenting the successful demonstration of an OMS Reference Service running in the OCE under test and communicating through a C++ CAL implementation. | J12: 1, 2, 3 | L12: (-1)_1 | M12: =AND(OR(IF(P12=TRUE,TRUE,FALSE),(IF(P12="N/A",NOT(ISBLANK(Q12)))))) -> FALSE | N12: STD-000350 (-1)_1: The functional test results show that during the successful demonstration, an OMS Reference Service ran in the OCE under test and communicated through a C++ CAL implementation. | O12: functional test results | P12: AC 1-1 Met?
A13: STD-000351 Tier 1, 2, 3 | B13: RQMT STD-000351 [An OMS OCE shall host a Java OMS CAL implementation.] | C13: =AND((OR(IF(F13=TRUE,TRUE,FALSE),IF(F13="N/A",TRUE,FALSE))),H13=TRUE) -> FALSE | F13: N/A | G13: (-1) | H13: =AND(M13) -> FALSE | I13: STD-000351 (-1): This requirement is verified by inspection of the functional test results documenting the successful demonstration of an OMS Reference Service running in the OCE under test and communicating through a Java CAL implementation. | J13: 1, 2, 3 | K13: If Java is prohibited due to system security policy, then only the C++ CAL implementation would be applicable for the OCE. | L13: (-1)_1 (-1)_2 | M13: =IF(P13=TRUE,TRUE,(AND((OR(IF(P14=TRUE,TRUE,FALSE),(IF(P14="N/A",NOT(ISBLANK(Q14))))))))) -> FALSE | N13: STD-000351 (-1)_1: If Java is prohibited due to system security policy, then this VR is satisfied. | O13: Platform Description Document (PDD) | P13: AC 1-1 Met?
N14: STD-000351 (-1)_2: The functional test results show that during the successful demonstration, an OMS Reference Service ran in the OCE under test and communicated through a Java CAL implementation. | O14: functional test results | P14: AC 1-2 Met?
A15: STD-000352 Tier 1, 2, 3 | B15: RQMT STD-000352 [An OMS OCE shall be capable of hosting at least one Service.] | C15: =AND((OR(IF(F15=TRUE,TRUE,FALSE),IF(F15="N/A",TRUE,FALSE))),H15=TRUE) -> FALSE | F15: N/A | G15: (-1) | H15: =AND(M15) -> FALSE | I15: STD-000352 (-1): This requirement is verified by inspection of the functional test results documenting the successful demonstration of an OMS Reference Service running in the OCE under test and communicating through the CAL implementation. | J15: 1, 2, 3 | L15: (-1)_1 | M15: =AND(OR(IF(P15=TRUE,TRUE,FALSE),(IF(P15="N/A",NOT(ISBLANK(Q15)))))) -> FALSE | N15: STD-000352 (-1)_1: The functional test results show that during the successful demonstration, an OMS Reference Service successfully executed in the OCE and communicated through the CAL implementation. | O15: functional test results | P15: AC 1-1 Met?
A16: STD-000354 Tier 1, 2, 3 | B16: RQMT STD-000354 [An OMS OCE shall synchronize system clock using an industry standard protocol identified in the “Approved Time Synchronization Protocols” table.] | C16: =AND((OR(IF(F16=TRUE,TRUE,FALSE),IF(F16="N/A",TRUE,FALSE))),H16=TRUE) -> FALSE | F16: N/A | G16: (-1) | H16: =AND(M16) -> FALSE | I16: STD-000354 (-1): This requirement is verified by inspection of the Platform Description Document (PDD) showing that time synchronization is supported by the OCE. | J16: 1, 2, 3 | K16: This information is documented in the “Time Reference and Time synchronization” section of the PDD. | L16: (-1)_1 | M16: =AND(OR(IF(P16=TRUE,TRUE,FALSE),(IF(P16="N/A",NOT(ISBLANK(Q16)))))) -> FALSE | N16: STD-000354 (-1)_1: The PDD documents the time synchronization mechanism(s) for the OCE. | O16: Platform Description Document (PDD) | P16: AC 1-1 Met?
A17: STD-000355 Tier 1, 2, 3 | B17: RQMT STD-000355 [An OMS OCE shall provide time to OCE-hosted Services through operating system interfaces.] | C17: =AND((OR(IF(F17=TRUE,TRUE,FALSE),IF(F17="N/A",TRUE,FALSE))),H17=TRUE) -> FALSE | F17: N/A | G17: (-1) | H17: =AND(M17) -> FALSE | I17: STD-000355 (-1): This requirement is verified by inspection of the Platform Description Document (PDD) showing that the OCE system clock is accessed through operating system interfaces. | J17: 1, 2, 3 | K17: This information is documented in the “Time Reference and Time Synchronization” section of the PDD. | L17: (-1)_1 | M17: =AND(OR(IF(P17=TRUE,TRUE,FALSE),(IF(P17="N/A",NOT(ISBLANK(Q17)))))) -> FALSE | N17: STD-000355 (-1)_1: The PDD identifies the operating system functions that can access the system clock. | O17: Platform Description Document (PDD) | P17: AC 1-1 Met?
A18: STD-000360 Tier 1, 2, 3 | B18: RQMT STD-000360 [An OMS OCE shall provide a Linux operating system with a minimum kernel version of 2.6.] | C18: =AND((OR(IF(F18=TRUE,TRUE,FALSE),IF(F18="N/A",TRUE,FALSE))),H18=TRUE) -> FALSE | F18: N/A | G18: (-1) | H18: =AND(M18) -> FALSE | I18: STD-000360 (-1): This requirement is verified by inspection of the Platform Description Document (PDD) showing that the OCE provides a Linux operating system with kernel version equal to or greater than 2.6. | J18: 1, 2, 3 | K18: This information is documented in the “OCE Processor Types, Operating Systems, and Configuration” section of the PDD. The following is a mechanism to determine the kernel version to populate the PDD. Run the “uname –a” command or similar that identifies the kernel version of the Linux operating system for the OCE. The value of this command displays the kernel version and if it is equal to or greater than 2.6 then this requirement is satisfied. | L18: (-1)_1 | M18: =AND(OR(IF(P18=TRUE,TRUE,FALSE),(IF(P18="N/A",NOT(ISBLANK(Q18)))))) -> FALSE | N18: STD-000360 (-1)_1: The PDD documents that the kernel version of the OCE Linux operating system is equal to or greater than version 2.6. | O18: Platform Description Document (PDD) | P18: AC 1-1 Met?
A19: STD-000362 Tier 1, 2, 3 | B19: RQMT STD-000362 [An OMS OCE shall provide a 64 bit Linux operating system when the OCE is hosted on a 64 bit processing board.] | C19: =AND((OR(IF(F19=TRUE,TRUE,FALSE),IF(F19="N/A",TRUE,FALSE))),H19=TRUE) -> FALSE | F19: N/A | G19: (-1) | H19: =AND(M19) -> FALSE | I19: STD-000362 (-1): This requirement is verified by inspection of the Platform Description Document (PDD) showing that an OCE hosted on a 64 bit processing board provides a 64 bit Linux operating system. | J19: 1, 2, 3 | K19: This requirement is only applicable when the OCE is hosted on 64 bit processing board. This information is documented in the “OCE Processor Types, Operating Systems, and Configuration” section of the PDD. | L19: (-1)_1 (-1)_2 | M19: =IF(P19=TRUE,TRUE,(AND((OR(IF(P20=TRUE,TRUE,FALSE),(IF(P20="N/A",NOT(ISBLANK(Q20))))))))) -> FALSE | N19: STD-000362 (-1)_1: If the OCE is not hosted on a 64 bit processing board, then this VR is satisfied. | O19: Platform Description Document (PDD) | P19: AC 1-1 Met?
N20: STD-000362 (-1)_2: The PDD documents that the OCE provides a 64 bit Linux operating system. | O20: Platform Description Document (PDD) | P20: AC 1-2 Met?
A21: STD-000365 Tier 1, 2, 3 | B21: RQMT STD-000365 [An OMS OCE shall provide a Façade implementation.] | C21: =AND((OR(IF(F21=TRUE,TRUE,FALSE),IF(F21="N/A",TRUE,FALSE))),H21=TRUE) -> FALSE | E21: STD-000381 | F21: =AND(C24) -> FALSE | G21: (-1) | H21: =AND(M21) -> FALSE | I21: STD-000365 (-1): This requirement is verified by the inspection of the [[Platform RQMT Checklist]] tab of the Platform Checklist, OMSC-CHK-003, that shows the subordinate requirements for RQMT STD-000365 have been met. | J21: 1, 2, 3 | L21: (-1)_1 | M21: =AND(OR(IF(P21=TRUE,TRUE,FALSE),(IF(P21="N/A",NOT(ISBLANK(Q21)))))) -> FALSE | N21: STD-000365 (-1)_1: The [[Platform RQMT Checklist]] tab of the Platform Checklist shows that the subordinate requirements listed in the “Subordinate Requirements” column for RQMT STD-000365 have been met. | O21: Platform Checklist | P21: =F21 -> FALSE | Q21: Auto Calculated
A22: STD-008663 Tier 1, 2, 3 | B22: RQMT STD-008663 [An OMS OCE shall provide a Java implementation.] | C22: =AND((OR(IF(F22=TRUE,TRUE,FALSE),IF(F22="N/A",TRUE,FALSE))),H22=TRUE) -> FALSE | E22: STD-000385 | F22: =AND(C25) -> FALSE | G22: (-1) | H22: =AND(M22) -> FALSE | I22: STD-008663 (-1): This requirement is verified by the inspection of the [[Platform RQMT Checklist]] tab of the Platform Checklist, OMSC-CHK-003, that shows the subordinate requirements for RQMT STD-008663 have been met. | J22: 1, 2, 3 | K22: If Java is prohibited due to system security policy, then only the C++ CAL implementation would be applicable for the OCE. | L22: (-1)_1 (-1)_2 | M22: =IF(P22=TRUE,TRUE,(AND((OR(IF(P23=TRUE,TRUE,FALSE),(IF(P23="N/A",NOT(ISBLANK(Q23))))))))) -> FALSE | N22: STD-008663 (-1)_1: If Java is prohibited due to system security policy, then this VR is satisfied. | O22: Platform Checklist | P22: AC 1-1 Met?
N23: STD-008663 (-1)_2: The [[Platform RQMT Checklist]] tab of the Platform Checklist shows that the subordinate requirements listed in the “Subordinate Requirements” column for RQMT STD-008663 have been met. | O23: Platform Checklist | P23: =F22 -> FALSE | Q23: Auto Calculated
A24: STD-000381 Tier 1, 2, 3 | B24: RQMT STD-000381 [An OMS OCE shall implement all allowed interfaces defined by the Operating System Façade Specification.] | C24: =AND((OR(IF(F24=TRUE,TRUE,FALSE),IF(F24="N/A",TRUE,FALSE))),H24=TRUE) -> FALSE | F24: N/A | G24: (-1) | H24: =AND(M24) -> FALSE | I24: STD-000381 (-1): This requirement is verified by inspection of the Platform Description Document (PDD) showing that the Façade implementation provides, at a minimum, the allowed interfaces defined in the Operating System Façade Specification, OMSC-SPC-005. | J24: 1, 2, 3 | K24: This information is documented in the “Isolation Layer” section of the PDD. The OCE can provide interfaces other than those interfaces identified as allowed in the Operating System Façade Specification. Specifically, it is discouraged, but permissible, for an OCE to provide the restricted interfaces. | L24: (-1)_1 | M24: =AND(OR(IF(P24=TRUE,TRUE,FALSE),(IF(P24="N/A",NOT(ISBLANK(Q24)))))) -> FALSE | N24: STD-000381 (-1)_1: The PDD documents that the Façade implementation provides the allowed interfaces defined in the Operating System Façade Specification. | O24: Platform Description Document (PDD) | P24: AC 1-1 Met?
A25: STD-000385 Tier 1, 2, 3 | B25: RQMT STD-000385 [An OMS OCE Java-based implementation shall provide a Java environment that is compliant with the Java specification.] | C25: =AND((OR(IF(F25=TRUE,TRUE,FALSE),IF(F25="N/A",TRUE,FALSE))),H25=TRUE) -> FALSE | F25: N/A | G25: (-1) | H25: =AND(M25) -> FALSE | I25: STD-000385 (-1): This requirement is verified by inspection of the Platform Description Document (PDD) showing that the OCE provides a Java environment that is compatible with a Long-Term Support (LTS) version of the Java specifications and is compatible with the Operating System (OS). | J25: 1, 2, 3 | K25: This information is documented in the “Build Environment and Tool Chain” section for the Java Environment in the PDD. If Java is prohibited due to system security policy, then only the C++ CAL implementation would be applicable for the OCE. The Java version may be considered for update as newer LTS versions become available. Services should provide any required libraries that are not provided by the Platform under the current Java language specification. | L25: (-1)_1 (-1)_2 (-1)_3 | M25: =IF(P25=TRUE,TRUE,(AND((OR(IF(P26=TRUE,TRUE,FALSE),(IF(P26="N/A",NOT(ISBLANK(Q26)))))),(OR(IF(P27=TRUE,TRUE,FALSE),(IF(P27="N/A",NOT(ISBLANK(Q27))))))))) -> FALSE | N25: STD-000385 (-1)_1: If Java is prohibited due to system security policy, then this VR is satisfied. | O25: Platform Description Document (PDD) | P25: AC 1-1 Met?
N26: STD-000385 (-1)_2: The PDD documents that the OCE provides a Java environment compatible with the OS. | O26: Platform Description Document (PDD) | P26: AC 1-2 Met?
N27: STD-000385 (-1)_3: The PDD documents that the OCE provides a Java environment that is capable of running Java SE 11 compatible bytecode. | O27: Platform Description Document (PDD) | P27: AC 1-3 Met?
A28: STD-000082 Tier 1, 2, 3 | B28: RQMT STD-000082 [A Tier 1 OMS Platform shall provide an OMS ASB.] | C28: =AND((OR(IF(F28=TRUE,TRUE,FALSE),IF(F28="N/A",TRUE,FALSE))),H28=TRUE) -> FALSE | E28: STD-000144 STD-000146 STD-009706 | F28: =AND(C2,C3,C4) -> FALSE | G28: (-1) | H28: =AND(M28) -> FALSE | I28: STD-000082 (-1): This requirement is verified by the inspection of the [[Platform RQMT Checklist]] tab of the Platform Checklist, OMSC-CHK-003, that shows the subordinate requirements for RQMT STD-000082 have been met. | J28: 1, 2, 3 | L28: (-1)_1 | M28: =AND(OR(IF(P28=TRUE,TRUE,FALSE),(IF(P28="N/A",NOT(ISBLANK(Q28)))))) -> FALSE | N28: STD-000082 (-1)_1: The [[Platform RQMT Checklist]] tab of the Platform Checklist shows that the subordinate requirements listed in the “Subordinate Requirements” column for RQMT STD-000082 have been met. | O28: Platform Checklist | P28: =F28 -> FALSE | Q28: Auto Calculated
A29: STD-000083 Tier 1, 2, 3 | B29: RQMT STD-000083 [A Tier 1 OMS Platform shall provide an OMS OCE.] | C29: =AND((OR(IF(F29=TRUE,TRUE,FALSE),IF(F29="N/A",TRUE,FALSE))),H29=TRUE) -> FALSE | E29: STD-000350 STD-000351 STD-000352 STD-000354 STD-000355 STD-000360 STD-000362 STD-000365 STD-008663 | F29: =AND(C12,C13,C15,C16,C17,C18,C19,C21,C22) -> FALSE | G29: (-1) | H29: =AND(M29) -> FALSE | I29: STD-000083 (-1): This requirement is verified by the inspection of the [[Platform RQMT Checklist]] tab of the Platform Checklist, OMSC-CHK-003, that shows the subordinate requirements for RQMT STD-000083 have been met. | J29: 1, 2, 3 | K29: A Platform provides an OCE for a Mission Package. The Mission Package Description Document (MPDD) identifies the Platform and any Subsystem(s) providing OCE implementation(s) in the Mission Package. An OCE will provide a Java implementation if it is not against system security policy. | L29: (-1)_1 | M29: =AND(OR(IF(P29=TRUE,TRUE,FALSE),(IF(P29="N/A",NOT(ISBLANK(Q29)))))) -> FALSE | N29: STD-000083 (-1)_1: The [[Platform RQMT Checklist]] tab of the Platform Checklist shows that the subordinate requirements listed in the “Subordinate Requirements” column for RQMT STD-000083 have been met. | O29: Platform Checklist | P29: =F29 -> FALSE | Q29: Auto Calculated
A30: STD-000085 Tier 1, 2, 3 | B30: RQMT STD-000085 [A Tier 1 OMS Platform shall be documented in a non-proprietary Platform Description Document in accordance with the OMS Platform Description Document Template.] | C30: =AND((OR(IF(F30=TRUE,TRUE,FALSE),IF(F30="N/A",TRUE,FALSE))),H30=TRUE) -> FALSE | F30: N/A | G30: (-1) (-2) (-3) (-4) (-5) (-6) (-7) (-8) (-9) (-10) | H30: =AND(M30,M31,M34,M36,M38,M40,M42,M44,M46,M48) -> FALSE | I30: STD-000085 (-1): This requirement is verified by inspection of the Platform Description Document (PDD) showing that the PDD is complete and complies with the current version of the PDD Template, OMSC-TMP-001; inspection results are recorded in the [[PDD]] tab of the Platform Checklist, OMSC-CHK-003. | J30: 1, 2, 3 | K30: “Current Version” in this context refers to the version of the PDD Template specified in the OMS Standard against which compliance is being measured. | L30: (-1)_1 | M30: =AND(OR(IF(P30=TRUE,TRUE,FALSE),(IF(P30="N/A",NOT(ISBLANK(Q30)))))) -> FALSE | N30: STD-000085 (-1)_1: The [[PDD]] tab of the Platform Checklist shows that the PDD is complete and complies with the current version of the PDD Template. | O30: Platform Checklist | P30: =PDD!B2 -> FALSE | Q30: Auto Calculated
I31: STD-000085 (-2): This requirement is verified by inspection of the delivered Platform Description Document (PDD) showing that the document does not include proprietary labels; that the PDD includes a Platform Network diagram; and that the Security Information Exchanges implemented by the Platform are documented in the PDD. | J31: 1, 2, 3 | K31: Although the PDD may contain references to proprietary documentation, the PDD itself must be non-proprietary. The “Security Addendum” section of the PDD identifies the unclassified and non-proprietary name of the Security Addendum document. The Security Addendum may be both classified and proprietary. The Security Addendum describes the Security Information Exchanges implemented by the Platform and provides additional, classified, and/or proprietary details relating to the security of the Platform. | L31: (-2)_1 (-2)_2 (-2)_3 | M31: =AND(OR(IF(P31=TRUE,TRUE,FALSE),(IF(P31="N/A",NOT(ISBLANK(Q31))))),(OR(IF(P32=TRUE,TRUE,FALSE),(IF(P32="N/A",NOT(ISBLANK(Q32)))))),(OR(IF(P33=TRUE,TRUE,FALSE),(IF(P33="N/A",NOT(ISBLANK(Q33))))))) -> FALSE | N31: STD-000085 (-2)_1: The delivered PDD has no proprietary labels applied to any of its pages. | O31: Platform Description Document (PDD) | P31: AC 2-1 Met?
N32: STD-000085 (-2)_2: The “Network” section of the PDD contains a Platform network diagram that shows the network architecture implementation; including the physical connections, the interface speeds, and any network limitations. | O32: Platform Description Document (PDD) | P32: AC 2-2 Met?
N33: STD-000085 (-2)_3: The PDD, or the PDD Security Addendum, documents the Security Information Exchanges implemented by the Platform. | O33: Platform Description Document (PDD) | P33: AC 2-3 Met?
I34: STD-000085 (-3): This requirement is verified by inspection of the Platform Description Document (PDD) showing the ports and protocols the Platform can use for data transfer are documented. | J34: 1, 2, 3 | K34: The PDD should provide instructions on how to configure data transfer capabilities. This information is documented in the “Ports & Protocols” section of the PDD. | L34: (-3)_1 (-3)_2 | M34: =IF(P34=TRUE,TRUE,(AND((OR(IF(P35=TRUE,TRUE,FALSE),(IF(P35="N/A",NOT(ISBLANK(Q35))))))))) -> FALSE | N34: STD-000085 (-3)_1: If no ports or protocols are used for data transfer, then this VR is satisfied. | O34: Platform Description Document (PDD) | P34: AC 3-1 Met?
N35: STD-000085 (-3)_2: The PDD documents the ports and protocols used for data transfer. | O35: Platform Description Document (PDD) | P35: AC 3-2 Met?
I36: STD-000085 (-4): This requirement is verified by inspection of the Platform Description Document (PDD) showing that the mechanism for restricting the ports and protocols for data transfers is documented. | J36: 1, 2, 3 | K36: This information is documented in the “Ports & Protocols” section of the PDD. | L36: (-4)_1 (-4)_2 | M36: =IF(P36=TRUE,TRUE,(AND((OR(IF(P37=TRUE,TRUE,FALSE),(IF(P37="N/A",NOT(ISBLANK(Q37))))))))) -> FALSE | N36: STD-000085 (-4)_1: If restricting ports or protocols for data transfers is not required, then this VR is satisfied. | O36: Platform Description Document (PDD) | P36: AC 4-1 Met?
N37: STD-000085 (-4)_2: The PDD documents the mechanism for restricting the ports and protocols for data transfers. | O37: Platform Description Document (PDD) | P37: AC 4-2 Met?
I38: STD-000085 (-5): This requirement is verified by inspection of the Platform Description Document (PDD) showing that the access control mechanism(s) the Platform can use for data storage are documented. | J38: 1, 2, 3 | K38: This information is documented in the “Data Storage Access Controls” section of the PDD. | L38: (-5)_1 (-5)_2 | M38: =IF(P38=TRUE,TRUE,(AND((OR(IF(P39=TRUE,TRUE,FALSE),(IF(P39="N/A",NOT(ISBLANK(Q39))))))))) -> FALSE | N38: STD-000085 (-5)_1: If access control for data storage is not required, then this VR is satisfied. | O38: Platform Description Document (PDD) | P38: AC 5-1 Met?
N39: STD-000085 (-5)_2: The PDD documents the access control mechanism(s) for data storage. | O39: Platform Description Document (PDD) | P39: AC 5-2 Met?
I40: STD-000085 (-6): This requirement is verified by inspection of the Platform Description Document (PDD) showing that the identification and authentication mechanism(s) the Platform can use for data transfer are documented. | J40: 1, 2, 3 | K40: This information is typically provided in the “Data Transfer Configuration” section of the PDD. | L40: (-6)_1 (-6)_2 | M40: =IF(P40=TRUE,TRUE,(AND((OR(IF(P41=TRUE,TRUE,FALSE),(IF(P41="N/A",NOT(ISBLANK(Q41))))))))) -> FALSE | N40: STD-000085 (-6)_1: If identification and authentication for data transfer is not required, then this VR is satisfied. | O40: Platform Description Document (PDD) | P40: AC 6-1 Met?
...

Sheet PDD
A2: Platform Description Document Compliant to OMSC-TMP-001, Revision M, dated 22 January 2026? | B2: =AND(TRUE,F5,F6,F7,F8,F9,F13,F14,F19,F26,F39,F56,F75,F86,F105,F114,F117,F123,F131,F133,F135,F137) -> FALSE
A4: Platform Description Document Template Item | B4: Compliance | C4: Per Template? | D4: N/A Rationale | E4: Compliance Met? | F4: Section Rollup | G4: Level | H4: Row
A5: <REQUIRED: Platform Description Document Contract Title> | B5: Required | C5: <Select> | E5: =IF($B5="Required",OR($C5=TRUE,AND($C5="N/A",NOT(ISBLANK($D5)))),IF($B5="Optional",TRUE,IF($B5="Required if applicable",OR($C5=TRUE,AND($C5="N/A",NOT(ISBLANK($D5)))),OR($C5=TRUE,AND($C5="N/A",NOT(ISBLANK($D5))))))) -> FALSE | F5: =AND(E5) -> FALSE | G5: 1 | H5: 5
A6: <REQUIRED: Date as DD Month YYYY> | B6: Required | C6: <Select> | E6: =IF($B6="Required",OR($C6=TRUE,AND($C6="N/A",NOT(ISBLANK($D6)))),IF($B6="Optional",TRUE,IF($B6="Required if applicable",OR($C6=TRUE,AND($C6="N/A",NOT(ISBLANK($D6)))),OR($C6=TRUE,AND($C6="N/A",NOT(ISBLANK($D6))))))) -> FALSE | F6: =AND(E6) -> FALSE | G6: 1 | H6: 6
A7: <REQUIRED: Organization> | B7: Required | C7: <Select> | E7: =IF($B7="Required",OR($C7=TRUE,AND($C7="N/A",NOT(ISBLANK($D7)))),IF($B7="Optional",TRUE,IF($B7="Required if applicable",OR($C7=TRUE,AND($C7="N/A",NOT(ISBLANK($D7)))),OR($C7=TRUE,AND($C7="N/A",NOT(ISBLANK($D7))))))) -> FALSE | F7: =AND(E7) -> FALSE | G7: 1 | H7: 7
A8: Required statements (may be more restrictive): DISCLAIMER: The discussion of non-federal entities, methods, products, or services does not imply any endorsement by the United States Government, the Department of Defense, or the Department of the Air Force. Distribution Statement A. Approved for public release: distribution is unlimited. | B8: Required | C8: <Select> | E8: =IF($B8="Required",OR($C8=TRUE,AND($C8="N/A",NOT(ISBLANK($D8)))),IF($B8="Optional",TRUE,IF($B8="Required if applicable",OR($C8=TRUE,AND($C8="N/A",NOT(ISBLANK($D8)))),OR($C8=TRUE,AND($C8="N/A",NOT(ISBLANK($D8))))))) -> FALSE | F8: =AND(E8) -> FALSE | G8: 1 | H8: 8
A9: Abstract | B9: Required | C9: <Select> | E9: =IF($B9="Required",OR($C9=TRUE,AND($C9="N/A",NOT(ISBLANK($D9)))),IF($B9="Optional",TRUE,IF($B9="Required if applicable",OR($C9=TRUE,AND($C9="N/A",NOT(ISBLANK($D9)))),OR($C9=TRUE,AND($C9="N/A",NOT(ISBLANK($D9))))))) -> FALSE | F9: =AND(E9,F10,F11,F12) -> FALSE | G9: 1 | H9: 9
A10: Open Mission Systems (OMS) is a non-proprietary open architecture for integrating subsystems and services into mission packages. | B10: Required | C10: <Select> | E10: =IF($B10="Required",OR($C10=TRUE,AND($C10="N/A",NOT(ISBLANK($D10)))),IF($B10="Optional",TRUE,IF($B10="Required if applicable",OR($C10=TRUE,AND($C10="N/A",NOT(ISBLANK($D10)))),OR($C10=TRUE,AND($C10="N/A",NOT(ISBLANK($D10))))))) -> FALSE | F10: =AND(E10) -> FALSE | G10: 2 | H10: 10
A11: This Platform Description Document (PDD) complies with the Platform Description Document (PDD) Template, OMSC-TMP-001, Revision M, dated 22 January 2026. | B11: Required | C11: <Select> | E11: =IF($B11="Required",OR($C11=TRUE,AND($C11="N/A",NOT(ISBLANK($D11)))),IF($B11="Optional",TRUE,IF($B11="Required if applicable",OR($C11=TRUE,AND($C11="N/A",NOT(ISBLANK($D11)))),OR($C11=TRUE,AND($C11="N/A",NOT(ISBLANK($D11))))))) -> FALSE | F11: =AND(E11) -> FALSE | G11: 2 | H11: 11
A12: The template is prescribed by the OMS Standard Version 2.5, OMSC-STD-001, Revision M, dated 22 January 2026. | B12: Required | C12: <Select> | E12: =IF($B12="Required",OR($C12=TRUE,AND($C12="N/A",NOT(ISBLANK($D12)))),IF($B12="Optional",TRUE,IF($B12="Required if applicable",OR($C12=TRUE,AND($C12="N/A",NOT(ISBLANK($D12)))),OR($C12=TRUE,AND($C12="N/A",NOT(ISBLANK($D12))))))) -> FALSE | F12: =AND(E12) -> FALSE | G12: 2 | H12: 12
A13: Revision Record | B13: Required | C13: <Select> | E13: =IF($B13="Required",OR($C13=TRUE,AND($C13="N/A",NOT(ISBLANK($D13)))),IF($B13="Optional",TRUE,IF($B13="Required if applicable",OR($C13=TRUE,AND($C13="N/A",NOT(ISBLANK($D13)))),OR($C13=TRUE,AND($C13="N/A",NOT(ISBLANK($D13))))))) -> FALSE | F13: =AND(E13) -> FALSE | G13: 1 | H13: 13
A14: 1 Overview | B14: Required | C14: <Select> | E14: =IF($B14="Required",OR($C14=TRUE,AND($C14="N/A",NOT(ISBLANK($D14)))),IF($B14="Optional",TRUE,IF($B14="Required if applicable",OR($C14=TRUE,AND($C14="N/A",NOT(ISBLANK($D14)))),OR($C14=TRUE,AND($C14="N/A",NOT(ISBLANK($D14))))))) -> FALSE | F14: =AND(E14,F15,F16) -> FALSE | G14: 1 | H14: 14
A15: Proprietary Notice: This document contains only non-proprietary information. Referenced documents conform to the Proprietary Notice statement for each major subsection. | B15: Required | C15: <Select> | E15: =IF($B15="Required",OR($C15=TRUE,AND($C15="N/A",NOT(ISBLANK($D15)))),IF($B15="Optional",TRUE,IF($B15="Required if applicable",OR($C15=TRUE,AND($C15="N/A",NOT(ISBLANK($D15)))),OR($C15=TRUE,AND($C15="N/A",NOT(ISBLANK($D15))))))) -> FALSE | F15: =AND(E15) -> FALSE | G15: 2 | H15: 15
A16: 1.1 References | B16: Required | C16: <Select> | E16: =IF($B16="Required",OR($C16=TRUE,AND($C16="N/A",NOT(ISBLANK($D16)))),IF($B16="Optional",TRUE,IF($B16="Required if applicable",OR($C16=TRUE,AND($C16="N/A",NOT(ISBLANK($D16)))),OR($C16=TRUE,AND($C16="N/A",NOT(ISBLANK($D16))))))) -> FALSE | F16: =AND(E16,F17,F18) -> FALSE | G16: 2 | H16: 16
A17: Proprietary Notice: References to external documents that provide for the data in this section may refer to proprietary documents. | B17: Required | C17: <Select> | E17: =IF($B17="Required",OR($C17=TRUE,AND($C17="N/A",NOT(ISBLANK($D17)))),IF($B17="Optional",TRUE,IF($B17="Required if applicable",OR($C17=TRUE,AND($C17="N/A",NOT(ISBLANK($D17)))),OR($C17=TRUE,AND($C17="N/A",NOT(ISBLANK($D17))))))) -> FALSE | F17: =AND(E17) -> FALSE | G17: 3 | H17: 17
A18: Table 1.1-1 Reference Documents | B18: Required | C18: <Select> | E18: =IF($B18="Required",OR($C18=TRUE,AND($C18="N/A",NOT(ISBLANK($D18)))),IF($B18="Optional",TRUE,IF($B18="Required if applicable",OR($C18=TRUE,AND($C18="N/A",NOT(ISBLANK($D18)))),OR($C18=TRUE,AND($C18="N/A",NOT(ISBLANK($D18))))))) -> FALSE | F18: =AND(E18) -> FALSE | G18: 3 | H18: 18
A19: 2 Platform | B19: Required | C19: <Select> | E19: =IF($B19="Required",OR($C19=TRUE,AND($C19="N/A",NOT(ISBLANK($D19)))),IF($B19="Optional",TRUE,IF($B19="Required if applicable",OR($C19=TRUE,AND($C19="N/A",NOT(ISBLANK($D19)))),OR($C19=TRUE,AND($C19="N/A",NOT(ISBLANK($D19))))))) -> FALSE | F19: =AND(E19,F20,F23) -> FALSE | G19: 1 | H19: 19
A20: 2.1 Platform Licenses | B20: Required | C20: <Select> | E20: =IF($B20="Required",OR($C20=TRUE,AND($C20="N/A",NOT(ISBLANK($D20)))),IF($B20="Optional",TRUE,IF($B20="Required if applicable",OR($C20=TRUE,AND($C20="N/A",NOT(ISBLANK($D20)))),OR($C20=TRUE,AND($C20="N/A",NOT(ISBLANK($D20))))))) -> FALSE | F20: =AND(E20,F21,F22) -> FALSE | G20: 2 | H20: 20
A21: Proprietary Notice: References to external documents that provide for the data in this section refer only to non-proprietary documents. | B21: Required | C21: <Select> | E21: =IF($B21="Required",OR($C21=TRUE,AND($C21="N/A",NOT(ISBLANK($D21)))),IF($B21="Optional",TRUE,IF($B21="Required if applicable",OR($C21=TRUE,AND($C21="N/A",NOT(ISBLANK($D21)))),OR($C21=TRUE,AND($C21="N/A",NOT(ISBLANK($D21))))))) -> FALSE | F21: =AND(E21) -> FALSE | G21: 3 | H21: 21
A22: Table 2.1-1 Platform Licenses | B22: Required | C22: <Select> | E22: =IF($B22="Required",OR($C22=TRUE,AND($C22="N/A",NOT(ISBLANK($D22)))),IF($B22="Optional",TRUE,IF($B22="Required if applicable",OR($C22=TRUE,AND($C22="N/A",NOT(ISBLANK($D22)))),OR($C22=TRUE,AND($C22="N/A",NOT(ISBLANK($D22))))))) -> FALSE | F22: =AND(E22) -> FALSE | G22: 3 | H22: 22
A23: 2.2 Platform Software Dependencies | B23: Required | C23: <Select> | E23: =IF($B23="Required",OR($C23=TRUE,AND($C23="N/A",NOT(ISBLANK($D23)))),IF($B23="Optional",TRUE,IF($B23="Required if applicable",OR($C23=TRUE,AND($C23="N/A",NOT(ISBLANK($D23)))),OR($C23=TRUE,AND($C23="N/A",NOT(ISBLANK($D23))))))) -> FALSE | F23: =AND(E23,F24,F25) -> FALSE | G23: 2 | H23: 23
A24: Proprietary Notice: References to external documents that provide for the data in this section may refer to proprietary documents. | B24: Required | C24: <Select> | E24: =IF($B24="Required",OR($C24=TRUE,AND($C24="N/A",NOT(ISBLANK($D24)))),IF($B24="Optional",TRUE,IF($B24="Required if applicable",OR($C24=TRUE,AND($C24="N/A",NOT(ISBLANK($D24)))),OR($C24=TRUE,AND($C24="N/A",NOT(ISBLANK($D24))))))) -> FALSE | F24: =AND(E24) -> FALSE | G24: 3 | H24: 24
A25: Table 2.2-1 Platform Software Dependencies | B25: Required | C25: <Select> | E25: =IF($B25="Required",OR($C25=TRUE,AND($C25="N/A",NOT(ISBLANK($D25)))),IF($B25="Optional",TRUE,IF($B25="Required if applicable",OR($C25=TRUE,AND($C25="N/A",NOT(ISBLANK($D25)))),OR($C25=TRUE,AND($C25="N/A",NOT(ISBLANK($D25))))))) -> FALSE | F25: =AND(E25) -> FALSE | G25: 3 | H25: 25
A26: 3 Abstract Service Bus (ASB) | B26: Required | C26: <Select> | E26: =IF($B26="Required",OR($C26=TRUE,AND($C26="N/A",NOT(ISBLANK($D26)))),IF($B26="Optional",TRUE,IF($B26="Required if applicable",OR($C26=TRUE,AND($C26="N/A",NOT(ISBLANK($D26)))),OR($C26=TRUE,AND($C26="N/A",NOT(ISBLANK($D26))))))) -> FALSE | F26: =AND(E26,F27,F28,F30) -> FALSE | G26: 1 | H26: 26
A27: Proprietary Notice: References to external documents that provide for the data in this section refer only to non-proprietary documents. | B27: Required | C27: <Select> | E27: =IF($B27="Required",OR($C27=TRUE,AND($C27="N/A",NOT(ISBLANK($D27)))),IF($B27="Optional",TRUE,IF($B27="Required if applicable",OR($C27=TRUE,AND($C27="N/A",NOT(ISBLANK($D27)))),OR($C27=TRUE,AND($C27="N/A",NOT(ISBLANK($D27))))))) -> FALSE | F27: =AND(E27) -> FALSE | G27: 2 | H27: 27
A28: 3.1 OMS Message Set | B28: Required | C28: <Select> | E28: =IF($B28="Required",OR($C28=TRUE,AND($C28="N/A",NOT(ISBLANK($D28)))),IF($B28="Optional",TRUE,IF($B28="Required if applicable",OR($C28=TRUE,AND($C28="N/A",NOT(ISBLANK($D28)))),OR($C28=TRUE,AND($C28="N/A",NOT(ISBLANK($D28))))))) -> FALSE | F28: =AND(E28,F29) -> FALSE | G28: 2 | H28: 28
A29: Table 3.1-1 OMS Message Set | B29: Required | C29: <Select> | E29: =IF($B29="Required",OR($C29=TRUE,AND($C29="N/A",NOT(ISBLANK($D29)))),IF($B29="Optional",TRUE,IF($B29="Required if applicable",OR($C29=TRUE,AND($C29="N/A",NOT(ISBLANK($D29)))),OR($C29=TRUE,AND($C29="N/A",NOT(ISBLANK($D29))))))) -> FALSE | F29: =AND(E29) -> FALSE | G29: 3 | H29: 29
A30: 3.2 Network | B30: Required | C30: <Select> | E30: =IF($B30="Required",OR($C30=TRUE,AND($C30="N/A",NOT(ISBLANK($D30)))),IF($B30="Optional",TRUE,IF($B30="Required if applicable",OR($C30=TRUE,AND($C30="N/A",NOT(ISBLANK($D30)))),OR($C30=TRUE,AND($C30="N/A",NOT(ISBLANK($D30))))))) -> FALSE | F30: =AND(E30,F31,F34,F37) -> FALSE | G30: 2 | H30: 30
A31: 3.2.1 Network Interconnect Diagram | B31: Required | C31: <Select> | E31: =IF($B31="Required",OR($C31=TRUE,AND($C31="N/A",NOT(ISBLANK($D31)))),IF($B31="Optional",TRUE,IF($B31="Required if applicable",OR($C31=TRUE,AND($C31="N/A",NOT(ISBLANK($D31)))),OR($C31=TRUE,AND($C31="N/A",NOT(ISBLANK($D31))))))) -> FALSE | F31: =AND(E31,F32,F33) -> FALSE | G31: 3 | H31: 31
A32: Figure 3.2-1 Network Interconnect Diagram | B32: Required | C32: <Select> | E32: =IF($B32="Required",OR($C32=TRUE,AND($C32="N/A",NOT(ISBLANK($D32)))),IF($B32="Optional",TRUE,IF($B32="Required if applicable",OR($C32=TRUE,AND($C32="N/A",NOT(ISBLANK($D32)))),OR($C32=TRUE,AND($C32="N/A",NOT(ISBLANK($D32))))))) -> FALSE | F32: =AND(E32) -> FALSE | G32: 4 | H32: 32
A33: Table 3.2-1 Network Segmentation | B33: Required | C33: <Select> | E33: =IF($B33="Required",OR($C33=TRUE,AND($C33="N/A",NOT(ISBLANK($D33)))),IF($B33="Optional",TRUE,IF($B33="Required if applicable",OR($C33=TRUE,AND($C33="N/A",NOT(ISBLANK($D33)))),OR($C33=TRUE,AND($C33="N/A",NOT(ISBLANK($D33))))))) -> FALSE | F33: =AND(E33) -> FALSE | G33: 4 | H33: 33
A34: 3.2.2 Ports & Protocols | B34: Required | C34: <Select> | E34: =IF($B34="Required",OR($C34=TRUE,AND($C34="N/A",NOT(ISBLANK($D34)))),IF($B34="Optional",TRUE,IF($B34="Required if applicable",OR($C34=TRUE,AND($C34="N/A",NOT(ISBLANK($D34)))),OR($C34=TRUE,AND($C34="N/A",NOT(ISBLANK($D34))))))) -> FALSE | F34: =AND(E34,F35,F36) -> FALSE | G34: 3 | H34: 34
A35: Table 3.2-2 Open Ports and Protocols | B35: Required | C35: <Select> | E35: =IF($B35="Required",OR($C35=TRUE,AND($C35="N/A",NOT(ISBLANK($D35)))),IF($B35="Optional",TRUE,IF($B35="Required if applicable",OR($C35=TRUE,AND($C35="N/A",NOT(ISBLANK($D35)))),OR($C35=TRUE,AND($C35="N/A",NOT(ISBLANK($D35))))))) -> FALSE | F35: =AND(E35) -> FALSE | G35: 4 | H35: 35
A36: Table 3.2-3 Product/Data and Data Transfer Servers | B36: Required | C36: <Select> | E36: =IF($B36="Required",OR($C36=TRUE,AND($C36="N/A",NOT(ISBLANK($D36)))),IF($B36="Optional",TRUE,IF($B36="Required if applicable",OR($C36=TRUE,AND($C36="N/A",NOT(ISBLANK($D36)))),OR($C36=TRUE,AND($C36="N/A",NOT(ISBLANK($D36))))))) -> FALSE | F36: =AND(E36) -> FALSE | G36: 4 | H36: 36
A37: 3.2.3 Network Address Information | B37: Required | C37: <Select> | E37: =IF($B37="Required",OR($C37=TRUE,AND($C37="N/A",NOT(ISBLANK($D37)))),IF($B37="Optional",TRUE,IF($B37="Required if applicable",OR($C37=TRUE,AND($C37="N/A",NOT(ISBLANK($D37)))),OR($C37=TRUE,AND($C37="N/A",NOT(ISBLANK($D37))))))) -> FALSE | F37: =AND(E37,F38) -> FALSE | G37: 3 | H37: 37
A38: Table 3.2-4 Networking Information | B38: Required | C38: <Select> | E38: =IF($B38="Required",OR($C38=TRUE,AND($C38="N/A",NOT(ISBLANK($D38)))),IF($B38="Optional",TRUE,IF($B38="Required if applicable",OR($C38=TRUE,AND($C38="N/A",NOT(ISBLANK($D38)))),OR($C38=TRUE,AND($C38="N/A",NOT(ISBLANK($D38))))))) -> FALSE | F38: =AND(E38) -> FALSE | G38: 4 | H38: 38
A39: 4 Data Transfer | B39: Required | C39: <Select> | E39: =IF($B39="Required",OR($C39=TRUE,AND($C39="N/A",NOT(ISBLANK($D39)))),IF($B39="Optional",TRUE,IF($B39="Required if applicable",OR($C39=TRUE,AND($C39="N/A",NOT(ISBLANK($D39)))),OR($C39=TRUE,AND($C39="N/A",NOT(ISBLANK($D39))))))) -> FALSE | F39: =AND(E39,F40,F41,F49,F51,F53) -> FALSE | G39: 1 | H39: 39
A40: Proprietary Notice: References to external documents that provide for the data in this section refer only to non-proprietary documents. | B40: Required | C40: <Select> | E40: =IF($B40="Required",OR($C40=TRUE,AND($C40="N/A",NOT(ISBLANK($D40)))),IF($B40="Optional",TRUE,IF($B40="Required if applicable",OR($C40=TRUE,AND($C40="N/A",NOT(ISBLANK($D40)))),OR($C40=TRUE,AND($C40="N/A",NOT(ISBLANK($D40))))))) -> FALSE | F40: =AND(E40) -> FALSE | G40: 2 | H40: 40
A41: 4.1 Data Storage | B41: Required | C41: <Select> | E41: =IF($B41="Required",OR($C41=TRUE,AND($C41="N/A",NOT(ISBLANK($D41)))),IF($B41="Optional",TRUE,IF($B41="Required if applicable",OR($C41=TRUE,AND($C41="N/A",NOT(ISBLANK($D41)))),OR($C41=TRUE,AND($C41="N/A",NOT(ISBLANK($D41))))))) -> FALSE | F41: =AND(E41,F42,F43,F45,F47) -> FALSE | G41: 2 | H41: 41
A42: Table 4.1-1 Platform Data Storage Details | B42: Required | C42: <Select> | E42: =IF($B42="Required",OR($C42=TRUE,AND($C42="N/A",NOT(ISBLANK($D42)))),IF($B42="Optional",TRUE,IF($B42="Required if applicable",OR($C42=TRUE,AND($C42="N/A",NOT(ISBLANK($D42)))),OR($C42=TRUE,AND($C42="N/A",NOT(ISBLANK($D42))))))) -> FALSE | F42: =AND(E42) -> FALSE | G42: 3 | H42: 42
...
