Workbook
Name _Toc256000163: 'Special Signals Tables'!#REF!
Name _Toc256000164: 'Special Signals Tables'!#REF!

Sheet WARNING NOTE
A6: WARNING NOTICE
A8: THIS CHECKLIST HAS FORMULAS THAT AUTOMATICALLY CALCULATE SUMMATIONS AND ROLL-UPS OF COMPLIANCE STATE. THESE FORMULAS MAY HAVE ERRORS THAT HAVE NOT BEEN DETECTED. PLEASE BE ADVISED THAT DUE TO THE POTENTIAL FOR AN ERROR IT IS RECOMMENDED THAT A MANUAL VERIFICATION BE PERFORMED BY THE PERSON OR ORGANIZATION FILLING OUT THE CHECKLIST TO ENSURE THAT THE CHECKLIST ACCURATELY REFLECTS THE STATE OF COMPLIANCE FOR THE OMS ELEMENT IN QUESTION.
A10: Notes for the User:
A12: This workbook has protection applied to preserve formulas and cross referencing.
A14: User input is only required/allowed in the blue shaded cells of each worksheet, except for the Cover, Abstract and Rev Table, which are user editable.

Sheet Cover
A3: <REQUIRED: ISOLATOR CHECKLIST TITLE>
A4: <OPTIONAL: Organization CDRL Number>
A5: <OPTIONAL: Organization Logo>
A6: Prepared By:
A7: <REQUIRED: Organization>
A8: <OPTIONAL: Address>
A10: DISCLAIMER: The discussion of non-federal entities, methods, products, or services does not imply any endorsement by the United States Government, the Department of Defense, or the Department of the Air Force.
A11: Distribution Statement A. Approved for public release: distribution is unlimited.

Sheet Abstract
A1: ABSTRACT
A2: < The abstract is REQUIRED and is a brief summary of the document that follows and is used to help the reader quickly ascertain the document's purpose and overall content. >
A3: < Before attempting to fill out this checklist, the Isolator compliance assessor should have access to the referenced Service Contract for the Isolator. >
A4: This Isolator Checklist complies with the OMS Standard Version 2.5, OMSC-STD-001, Revision M, 22 January 2026.

Sheet Rev
A2: REVISION RECORD
A4: REVISION | B4: DATE | C4: DESCRIPTION
A5: - | B5: dd-mmm-yy | C5: Original

Sheet Tier Compliance
A1: =IF((AND(C4:C18))=TRUE,"Meets Isolator RQMTs for a Tier 1, Tier 2, or Tier 3 OMS Mission Package", IF((AND(C4:C14))=TRUE,"Meets Isolator RQMTs for a Tier 1 or Tier 2 OMS Mission Package",IF((AND(C4:C14))=TRUE,"Meets Isolator RQMTs for a Tier 1 OMS Mission Package", "Does Not Meet Isolator RQMTs for an OMS Mission Package"))) -> Does Not Meet Isolator RQMTs for an OMS Mission Package
A3: RQMT ID | B3: RQMT Topic | C3: RQMT Met?
A4: STD-000427 Tier 1, 2, 3 | B4: Service Contract Required | C4: ='Isolator RQMT Checklist'!C2 -> FALSE
A5: STD-000431 Tier 1, 2, 3 | B5: Use OMS CAL | C5: ='Isolator RQMT Checklist'!C20 -> FALSE
A6: STD-006939 Tier 1, 2, 3 | B6: Select Data Formats | C6: ='Isolator RQMT Checklist'!C22 -> TRUE
A7: STD-006940 Tier 1, 2, 3 | B7: Select Corresponding Protocols or APIs | C7: ='Isolator RQMT Checklist'!C30 -> TRUE
A8: STD-010121 Tier 1, 2, 3 | B8: Select Corresponding Protocols or APIs | C8: ='Isolator RQMT Checklist'!C38 -> TRUE
A9: STD-006941 Tier 1, 2, 3 | B9: Select Corresponding Protocols or APIs | C9: ='Isolator RQMT Checklist'!C46 -> TRUE
A10: STD-006942 Tier 1, 2, 3 | B10: Use URI formats | C10: ='Isolator RQMT Checklist'!C54 -> TRUE
A11: STD-008664 Tier 1, 2, 3 | B11: Report Status | C11: ='Isolator RQMT Checklist'!C61 -> FALSE
A12: STD-008665 Tier 1, 2, 3 | B12: Implement Configurable Periodicity | C12: ='Isolator RQMT Checklist'!C64 -> FALSE
A13: STD-008666 Tier 1, 2, 3 | B13: Implement Periodic Update Rate | C13: ='Isolator RQMT Checklist'!C68 -> FALSE
A14: STD-009707 Tier 1, 2, 3 | B14: Document Cybersecurity posture | C14: ='Isolator RQMT Checklist'!C69 -> FALSE
A15: STD-006939 Tier 3 | B15: Select Data Formats | C15: ='Isolator RQMT Checklist'!C26 -> TRUE
A16: STD-006940 Tier 3 | B16: Select Corresponding Protocols or APIs | C16: ='Isolator RQMT Checklist'!C34 -> TRUE
A17: STD-010121 Tier 3 | B17: Select Corresponding Protocols or APIs | C17: ='Isolator RQMT Checklist'!C42 -> TRUE
A18: STD-006941 Tier 3 | B18: Select Corresponding Protocols or APIs | C18: ='Isolator RQMT Checklist'!C50 -> TRUE

Sheet Isolator RQMT Checklist
A1: RQMT ID | B1: RQMT Text | C1: RQMT Met? | D1: Clarification | E1: Subordinate RQMTS | F1: Sub RQMTS Met? | G1: VR List | H1: All VRs Met? | I1: Verification Requirement (VR) | J1: VR Tier | K1: Guidance | L1: AC List | M1: VR Met? | N1: Acceptance Criteria (AC) | O1: Assessed Article | P1: AC Met? | Q1: N/A Rationale
A2: STD-000427 Tier 1, 2, 3 | B2: RQMT STD-000427 [An OMS Isolator shall be documented in a non-proprietary Service Contract, in accordance with the OMS Service Contract Template, for its interfaces that cross the OMS-facing Isolator boundary.] | C2: =AND((OR(IF(F2=TRUE,TRUE,FALSE),IF(F2="N/A",TRUE,FALSE))),H2=TRUE) -> FALSE | F2: N/A | G2: (-1) (-2) (-3) (-4) (-5) (-6) (-7) (-8) (-9) (-10) | H2: =AND(M2,M3,M4,M6,M8,M10,M12,M14,M16,M18) -> FALSE | I2: STD-000427 (-1): This requirement is verified by inspection of the delivered Service Contract for the Isolator showing that the Service Contract is complete and complies with the current version of the Service Contract Template, OMSC-TMP-003; inspection results are recorded in the [[Service Contract]] tab of the Isolator Checklist, OMSC-CHK-006. | J2: 1, 2, 3 | K2: “Current Version” in this context refers to the version of the Service Contract Template specified in the OMS Standard against which compliance is being measured. | L2: (-1)_1 | M2: =AND(OR(IF(P2=TRUE,TRUE,FALSE),(IF(P2="N/A",NOT(ISBLANK(Q2)))))) -> FALSE | N2: STD-000427 (-1)_1: The [[Service Contract]] tab of the Isolator Checklist shows that the delivered Service Contract is complete and complies with the current version of the Service Contract Template. | O2: Isolator Checklist | P2: ='Service Contract'!B2 -> FALSE | Q2: Auto Calculated
I3: STD-000427 (-2): This requirement is verified by inspection of the delivered Service Contract for the Isolator for proprietary labels. | J3: 1, 2, 3 | K3: Although a Service Contract may contain references to proprietary documentation, the Service Contract itself must be non-proprietary. | L3: (-2)_1 | M3: =AND(OR(IF(P3=TRUE,TRUE,FALSE),(IF(P3="N/A",NOT(ISBLANK(Q3)))))) -> FALSE | N3: STD-000427 (-2)_1: The delivered Service Contract for the Isolator has no proprietary labels applied to any of its pages. | O3: Service Contract | P3: AC 2-1 Met?
I4: STD-000427 (-3): This requirement is verified by inspection of the Service Contract for the Isolator showing that each “messaging” data exchange that crosses the OMS-facing Isolator boundary and is implemented by the Isolator, is documented in the delivered Service Contract; the inspection results are recorded in the appropriate tabs in the Isolator Checklist, OMSC-CHK-006. | J4: 1, 2, 3 | K4: OMS defines four types of data exchanges: (1) messaging, (2) data transfer, (3) special signals, and (4) security information exchanges. The intent is that each OMS Data Exchange and non-OMS data exchange that crosses the OMS-facing Isolator boundary is documented in the Service Contract. Security information exchanges are not applicable to an OMS Isolator. This VR verifies that the “messaging” data exchanges are documented in the Service Contract. Inspection results are documented in the Isolator Checklist; OMS Messages in the [[OMS Msgs]] tab and Non-OMS Messages in the [[Non-OMS Msgs]] tab. | L4: (-3)_1 (-3)_2 | M4: =AND(OR(IF(P4=TRUE,TRUE,FALSE),(IF(P4="N/A",NOT(ISBLANK(Q4))))),(OR(IF(P5=TRUE,TRUE,FALSE),(IF(P5="N/A",NOT(ISBLANK(Q5))))))) -> FALSE | N4: STD-000427 (-3)_1: The [[OMS Msgs]] tab of the Isolator Checklist has been completed for each OMS Message crossing the OMS-facing Isolator boundary and documented in the delivered Service Contract. | O4: Isolator Checklist | P4: ='OMS Msgs'!BN19 -> FALSE | Q4: Auto Calculated
N5: STD-000427 (-3)_2: The [[Non-OMS Msgs]] tab of the Isolator Checklist has been completed for each Non-OMS Message crossing the OMS-facing Isolator boundary and documented in the delivered Service Contract. | O5: Isolator Checklist | P5: ='Non-OMS Msgs'!I7 -> N/A | Q5: ='Non-OMS Msgs'!J7 -> No Non-OMS Msgs
I6: STD-000427 (-4): This requirement is verified by inspection of the [[Non-OMS Msgs]] tab of the Isolator Checklist showing that there are no Non-OMS Messages crossing the OMS-facing Isolator boundary. | J6: 1, 2, 3 | K6: The use of Non-OMS Messages are not OMS compliant. | L6: (-4)_1 (-4)_2 | M6: =AND(OR(IF(P6=TRUE,TRUE,FALSE),(IF(P6="N/A",NOT(ISBLANK(Q6))))),(OR(IF(P7=TRUE,TRUE,FALSE),(IF(P7="N/A",NOT(ISBLANK(Q7))))))) -> TRUE | N6: STD-000427 (-4)_1: If the [[Non-OMS Msgs]] tab of the Isolator Checklist shows there are no Non-OMS Messages crossing the OMS-facing Isolator boundary; then this VR is satisfied. | O6: Isolator Checklist | P6: ='Non-OMS Msgs'!I5 -> TRUE | Q6: Auto Calculated
N7: STD-000427 (-4)_2: If the [[Non-OMS Msgs]] tab of the Isolator Checklist documents any Non-OMS Messages crossing the OMS-facing Isolator boundary, the entry for each message includes the name of the Non-OMS Message, and supporting information/rationale as to why the Non-OMS Message could not be implemented as an OMS Message as defined in the OMS Standard. | O7: Isolator Checklist | P7: ='Non-OMS Msgs'!I6 -> N/A | Q7: ='Non-OMS Msgs'!J6 -> No Non-OMS Msgs
I8: STD-000427 (-5): This requirement is verified by inspection of the Service Contract for the Isolator showing that each “data transfer” data exchange, that crosses the OMS-facing boundary and is implemented by the Isolator, is documented in the delivered Service Contract; the inspection results are recorded in the appropriate tabs in the Isolator Checklist, OMSC-CHK-006. | J8: 1, 2, 3 | K8: This VR verifies that the “data transfer” data exchanges are documented in the Service Contract. Inspection results are documented in the Isolator Checklist; OMS Data Transfers in the [[OMS Data Transfer]] tab and Non-OMS Data Transfers in the [[Non-OMS Data Transfer]] tab. | L8: (-5)_1 (-5)_2 | M8: =AND(OR(IF(P8=TRUE,TRUE,FALSE),(IF(P8="N/A",NOT(ISBLANK(Q8))))),(OR(IF(P9=TRUE,TRUE,FALSE),(IF(P9="N/A",NOT(ISBLANK(Q9))))))) -> TRUE | N8: STD-000427 (-5)_1: The [[OMS Data Transfer]] tab of the Isolator Checklist has been completed for each OMS Data Transfer crossing the OMS-facing Isolator boundary and documented in the delivered Service Contract. | O8: Isolator Checklist | P8: ='OMS Data Transfer'!T38 -> N/A | Q8: ='OMS Data Transfer'!U38 -> No OMS Data Transfer
N9: STD-000427 (-5)_2: The [[Non-OMS Data Transfer]] tab of the Isolator Checklist has been completed for each Non-OMS Data Transfer crossing the OMS-facing Isolator boundary and documented in the delivered Service Contract. | O9: Isolator Checklist | P9: ='Non-OMS Data Transfer'!V32 -> N/A | Q9: ='Non-OMS Data Transfer'!W32 -> Invalid or No Non-OMS Combination for Data Type and Formats
I10: STD-000427 (-6): This requirement is verified by inspection of the Service Contract for the Isolator showing that each “special signal” data exchange, that crosses the OMS-facing Isolator boundary and is implemented by the Isolator, is documented in the delivered Service Contract; the inspection results are recorded in the appropriate tabs in the Isolator Checklist, OMSC-CHK-006. | J10: 1, 2, 3 | K10: This VR verifies that the “special signals” data exchanges are documented in the Service Contract. Inspection results are documented in the Isolator Checklist; OMS Special Signals are documented in the [[OMS Special Signals]] tab and non-OMS special signals are documented in the [[Non-OMS Special Signals]] tab of the Isolator Checklist. | L10: (-6)_1 (-6)_2 | M10: =AND(OR(IF(P10=TRUE,TRUE,FALSE),(IF(P10="N/A",NOT(ISBLANK(Q10))))),(OR(IF(P11=TRUE,TRUE,FALSE),(IF(P11="N/A",NOT(ISBLANK(Q11))))))) -> TRUE | N10: STD-000427 (-6)_1: The [[OMS Special Signals]] tab of the Isolator Checklist has been completed for each OMS Special Signal crossing the OMS-facing Isolator boundary and documented in the delivered Service Contract. | O10: Isolator Checklist | P10: ='OMS Special Signals'!O4 -> N/A | Q10: ='OMS Special Signals'!P4 -> No OMS Special Signals
N11: STD-000427 (-6)_2: The [[Non-OMS Special Signals]] tab of the Isolator Checklist has been completed for each non-OMS special signal crossing the OMS-facing Isolator boundary and documented in the delivered Service Contract. | O11: Isolator Checklist | P11: ='Non-OMS Special Signals'!T10 -> TRUE | Q11: Auto Calculated
I12: STD-000427 (-7): This requirement is verified by inspection of the Service Contract for the Isolator showing that the ports and protocols the Isolator can use for data transfer are documented. | J12: 1, 2, 3 | K12: This information is typically provided in the “Data Transfer Ports and Protocols” section of the Service Contract. | L12: (-7)_1 (-7)_2 | M12: =IF(P12=TRUE,TRUE,(AND((OR(IF(P13=TRUE,TRUE,FALSE),(IF(P13="N/A",NOT(ISBLANK(Q13))))))))) -> FALSE | N12: STD-000427 (-7)_1: If no ports or protocols are used for data transfer, then this VR is satisfied. | O12: Service Contract | P12: AC 7-1 Met?
N13: STD-000427 (-7)_2: The ports and protocols for data transfer are documented in the Service Contract. | O13: Service Contract | P13: AC 7-2 Met?
I14: STD-000427 (-8): This requirement is verified by inspection of the Service Contract for the Isolator showing that the confidentiality mechanism(s) the Isolator can use for data transfer are documented. | J14: 1, 2, 3 | K14: This information is typically provided in the “Data Transfer Confidentiality Mechanisms” section of the Service Contract. | L14: (-8)_1 (-8)_2 | M14: =IF(P14=TRUE,TRUE,(AND((OR(IF(P15=TRUE,TRUE,FALSE),(IF(P15="N/A",NOT(ISBLANK(Q15))))))))) -> FALSE | N14: STD-000427 (-8)_1: If confidentiality for data transfer is not required, then this VR is satisfied. | O14: Service Contract | P14: AC 8-1 Met?
N15: STD-000427 (-8)_2: The confidentiality mechanism(s) for data transfer are documented in the Service Contract. | O15: Service Contract | P15: AC 8-2 Met?
I16: STD-000427 (-9): This requirement is verified by inspection of the Service Contract for the Isolator showing that the integrity mechanism(s) the Isolator can use for data transfer are documented. | J16: 1, 2, 3 | K16: This information is typically provided in the “Data Transfer Integrity Mechanisms” section of the Service Contract. | L16: (-9)_1 (-9)_2 | M16: =IF(P16=TRUE,TRUE,(AND((OR(IF(P17=TRUE,TRUE,FALSE),(IF(P17="N/A",NOT(ISBLANK(Q17))))))))) -> FALSE | N16: STD-000427 (-9)_1: If integrity for data transfer is not required, then this VR is satisfied. | O16: Service Contract | P16: AC 9-1 Met?
N17: STD-000427 (-9)_2: The integrity mechanism(s) for data transfer are documented in the Service Contract. | O17: Service Contract | P17: AC 9-2 Met?
I18: STD-000427 (-10): This requirement is verified by inspection of the Service Contract for the Isolator showing that the failure behavior(s) the Isolator can use for data transfer are documented. | J18: 1, 2, 3 | K18: This information is typically provided in the “Data Transfer Failure Behaviors” section of the Service Contract. | L18: (-10)_1 (-10)_2 | M18: =IF(P18=TRUE,TRUE,(AND((OR(IF(P19=TRUE,TRUE,FALSE),(IF(P19="N/A",NOT(ISBLANK(Q19))))))))) -> FALSE | N18: STD-000427 (-10)_1: If failure behavior for data transfer is not required, then this VR is satisfied. | O18: Service Contract | P18: AC 10-1 Met?
N19: STD-000427 (-10)_2: The failure behavior(s) for data transfer are documented in the Service Contract. | O19: Service Contract | P19: AC 10-2 Met?
A20: STD-000431 Tier 1, 2, 3 | B20: RQMT STD-000431 [An OMS Isolator shall use the OMS CAL, for its interfaces that cross the OMS-facing Isolator boundary, to send and/or receive OMS Messages over the OMS ASB.] | C20: =AND((OR(IF(F20=TRUE,TRUE,FALSE),IF(F20="N/A",TRUE,FALSE))),H20=TRUE) -> FALSE | F20: N/A | G20: (-1) | H20: =AND(M20) -> FALSE | I20: STD-000431 (-1): This requirement is verified by inspection of the Service Contract for the Isolator and the associated functional test results showing that each OMS Message used by the Isolator as an input/output message has successfully passed through a CAL between the Isolator and a test harness. The [[OMS Msgs]] tab of the Isolator Checklist, OMSC-CHK-006 is completed by listing each OMS Message used by the Isolator and documenting the location of the functional test results. | J20: 1, 2, 3 | K20: Data exchanges over the OMS ASB that are not made using the OMS Message Schema are fully identified and documented in the Service Contract. Proprietary data exchanges over the OMS ASB are not OMS compliant. Isolators connected to the OMS ASB may have some non-OMS interactions, but these non-OMS interactions will impact the OMS Tier level for the Mission Package. Isolators do not need to be hosted in an OCE to be compliant. It is entirely possible for an Isolator to be hosted inside an OMS-compliant Subsystem. Additionally, Isolators that have special requirements may be hosted outside of the OCE. Regardless of where Isolators are hosted, all OMS-compliant Isolators use the OMS CAL when communicating across the ASB. The Starter Kit CAL or a CAL from another program is sufficient for testing this requirement. | L20: (-1)_1 (-1)_2 | M20: =AND(OR(IF(P20=TRUE,TRUE,FALSE),(IF(P20="N/A",NOT(ISBLANK(Q20))))),(OR(IF(P21=TRUE,TRUE,FALSE),(IF(P21="N/A",NOT(ISBLANK(Q21))))))) -> FALSE | N20: STD-000431 (-1)_1: The [[OMS Msgs]] tab of the Isolator Checklist has been completed and identifies each OMS Message used by the Isolator and the location of the associated functional test results for each OMS Message. | O20: Isolator Checklist | P20: ='OMS Msgs'!BN20 -> FALSE | Q20: Auto Calculated
N21: STD-000431 (-1)_2: The functional test results for the Isolator show that each OMS Message used by the Isolator and identified as an input/output message in the Service Contract, has been tested and has successfully passed through a CAL between the Isolator and a test harness. | O21: functional test results | P21: AC 1-2 Met?
A22: STD-006939 Tier 1, 2, 3 | B22: RQMT STD-006939 [For each data type identified in column A of the “Data Transfer Formats, APIs, and Protocols” table, an OMS Isolator shall select from the corresponding data formats in column B of the “Data Transfer Formats, APIs, and Protocols” table for data transfers that cross the OMS-facing Isolator boundary.] | C22: =AND((OR(IF(F22=TRUE,TRUE,FALSE),IF(F22="N/A",TRUE,FALSE))),H22=TRUE) -> TRUE | F22: N/A | G22: (-1) | H22: =AND(M22) -> TRUE | I22: STD-006939 (-1): This requirement is verified by inspection of the Service Contract for the Isolator for each data transfer that crosses the OMS-facing Isolator boundary; the data type per column A and the data format per column B is identified for each data transfer and compared to the permitted combinations listed in the “Data Transfer Formats, APIs, and Protocols” table; the inspection results are recorded in the appropriate tabs of the Isolator Checklist, OMSC-CHK-006. | J22: 1, 2, 3 | K22: Data transfers that use one of the permitted combinations per the “Data Transfer Formats, APIs, and Protocols” table are recorded in the [[OMS Data Transfer]] tab; data transfers not using one of the permitted combinations are recorded in the [[Non-OMS Data Transfer]] tab of the Isolator Checklist. If the protocols, APIs, and/or formats listed in the “Data Transfer Formats, APIs, and Protocols” table are not sufficient, an explanation as to why that is so should be captured in the “Data Transfer” section of the Service Contract. Details of any non-proprietary protocol, data format, or API that is not represented in the “Data Transfer Formats, APIs, and Protocols” table should be fully documented (or provide corresponding reference(s)) in the “Data Transfer” section of the Service Contract. The following restrictions apply for all OMS Data Transfer combinations: 1) does not overlap with OMS Messages, 2) does not overlap with any other OMS Data Exchanges, and 3) does not transfer external standards second hand. Non-OMS Data Transfers are typically restricted to OMS compliance Tier 1. However, when an OACWG-approved Change Request is identified, then the Non-OMS Data Transfer will be assessed at the maximum allowed Tier specified by the OACWG. | L22: (-1)_1 (-1)_2 (-1)_3 (-1)_4 | M22: =AND(OR(IF(P22=TRUE,TRUE,FALSE),(IF(P22="N/A",NOT(ISBLANK(Q22))))),(OR(IF(P23=TRUE,TRUE,FALSE),(IF(P23="N/A",NOT(ISBLANK(Q23)))))),(OR(IF(P24=TRUE,TRUE,FALSE),(IF(P24="N/A",NOT(ISBLANK(Q24)))))),(OR(IF(P25=TRUE,TRUE,FALSE),(IF(P25="N/A",NOT(ISBLANK(Q25))))))) -> TRUE | N22: STD-006939 (-1)_1: If, for each data transfer crossing the OMS-facing Isolator boundary, the [[OMS Data Transfer]] tab of the Isolator Checklist shows that the data format in column B corresponds to the data type per column A as listed in the “Data Transfer Formats, APIs, and Protocols” table, including conforming to specified restrictions, then this VR is satisfied. | O22: Isolator Checklist | P22: ='OMS Data Transfer'!T33 -> N/A | Q22: ='OMS Data Transfer'!U33 -> No OMS Data Transfer
N23: STD-006939 (-1)_2: Each data transfer using a data type/data format combination that is not listed in the “Data Transfer Formats, APIs, and Protocols” table, but is covered by the “Non-OMS Data Transfers” table, is identified in the [[Non-OMS Data Transfer]] tab. | O23: Isolator Checklist | P23: ='Non-OMS Data Transfer'!V25 -> N/A | Q23: ='Non-OMS Data Transfer'!W25 -> Invalid or No Non-OMS Combination for Data Type and Formats
N24: STD-006939 (-1)_3: A description of the data format is provided for each Non-OMS Data Transfer listed in the [[Non-OMS Data Transfer]] tab. | O24: Isolator Checklist | P24: ='Non-OMS Data Transfer'!V30 -> N/A | Q24: ='Non-OMS Data Transfer'!W30 -> Invalid or No Non-OMS Combination for Data Type and Formats
N25: STD-006939 (-1)_4: A rationale is provided for each Non-OMS Data Transfer listed in the [[Non-OMS Data Transfer]] tab explaining why the data transfer could not be implemented using a permitted combination per the “Data Transfer Formats, APIs, and Protocols” table. | O25: Isolator Checklist | P25: ='Non-OMS Data Transfer'!V31 -> N/A | Q25: ='Non-OMS Data Transfer'!W31 -> Invalid or No Non-OMS Combination for Data Type and Formats
A26: STD-006939 Tier 3 | B26: RQMT STD-006939 [For each data type identified in column A of the “Data Transfer Formats, APIs, and Protocols” table, an OMS Isolator shall select from the corresponding data formats in column B of the “Data Transfer Formats, APIs, and Protocols” table for data transfers that cross the OMS-facing Isolator boundary.] | C26: =AND((OR(IF(F26=TRUE,TRUE,FALSE),IF(F26="N/A",TRUE,FALSE))),H26=TRUE) -> TRUE | F26: N/A | G26: (-1) (-2) (-3) | H26: =AND(M22,M26,M27) -> TRUE | I26: STD-006939 (-2): This requirement is verified by inspection of the Service Contract documentation for each data transfer that crosses the OMS-facing Isolator boundary; the data type per column A and the data format per column B are identified for each data transfer and compared to the permitted combinations listed in the “Data Transfer Formats, APIs, and Protocols” table where the Max Assessed Tier value in column F is 3; the inspection results are recorded in the appropriate tabs of the Isolator Checklist, OMSC-CHK-006. | J26: 3 | K26: Data transfers that use one of the permitted combinations for Max Assessed Tier of 3 per the “Data Transfer Formats, APIs, and Protocols” table are recorded in the [[OMS Data Transfer]] tab. | L26: (-2)_1 | M26: =AND(OR(IF(P26=TRUE,TRUE,FALSE),(IF(P26="N/A",NOT(ISBLANK(Q26)))))) -> TRUE | N26: STD-006939 (-2)_1: If, for each data transfer crossing the OMS-facing Isolator boundary, the [[OMS Data Transfer]] tab of the Isolator Checklist shows that the data format in column B corresponds to the data type per column A as listed in the “Data Transfer Formats, APIs, and Protocols” table where the Max Assessed Tier value in column F is 3, then this VR is satisfied. | O26: Isolator Checklist | P26: ='OMS Data Transfer'!T32 -> TRUE | Q26: Auto Calculated
I27: STD-006939 (-3): This requirement is verified by inspection of the Change Request documentation which adds each data type/data format combination listed in the [[Non-OMS Data Transfer]] tab of the Isolator Checklist, OMSC-CHK-006. | J27: 3 | K27: Submission of a Change Request is required to: 1. Add a format, protocol, or API, or 2. Use an existing OMS format, protocol, or API to transfer a type of data not covered by the “Data Transfer Formats, APIs, and Protocols” table. This Change Request will be considered part of compliance verification and validation. The following artifacts should be reviewed as part of the Change Request during the OACWG change process: 1. Full definition of any Data Transfer formats, protocols, and APIs proposed to be changed/added/deleted. 2. Red-lined versions of all Standard documentation affected by the change. 3. Test plan that shows testing or use of these Data Transfer formats and any progress should be included. 4. Response to any issues where this material is presented. It is the expectation that the Isolator is using the Change Request update as approved by the OACWG. | L27: (-3)_1 (-3)_2 (-3)_3 | M27: =AND(OR(IF(P27=TRUE,TRUE,FALSE),(IF(P27="N/A",NOT(ISBLANK(Q27))))),(OR(IF(P28=TRUE,TRUE,FALSE),(IF(P28="N/A",NOT(ISBLANK(Q28)))))),(OR(IF(P29=TRUE,TRUE,FALSE),(IF(P29="N/A",NOT(ISBLANK(Q29))))))) -> TRUE | N27: STD-006939 (-3)_1: If there are no Non-OMS Data Transfers listed in the [[Non-OMS Data Transfer]] tab, then this VR is satisfied. | O27: Isolator Checklist | P27: ='Non-OMS Data Transfer'!V33 -> TRUE | Q27: Auto Calculated
N28: STD-006939 (-3)_2: A Change Request documenting each Non-OMS Data Transfer identified in the [[Non-OMS Data Transfer]] tab and adding the required changes to the “Data Transfer Formats, APIs, and Protocols” table where the Max Assessed Tier value in column F is 3 has been submitted to and approved by the OACWG for the Change Request. | O28: Change Request | P28: ='Non-OMS Data Transfer'!V34 -> N/A | Q28: ='Non-OMS Data Transfer'!W34 -> Invalid or No Non-OMS Combination for Data Type and Formats
N29: STD-006939 (-3)_3: The Change Request ID of the Change Request has been documented in the [[Non-OMS Data Transfer]] tab. | O29: Isolator Checklist | P29: ='Non-OMS Data Transfer'!V36 -> N/A | Q29: ='Non-OMS Data Transfer'!W36 -> Invalid or No Non-OMS Combination for Data Type and Formats
A30: STD-006940 Tier 1, 2, 3 | B30: RQMT STD-006940 [For each data type identified in column A of the “Data Transfer Formats, APIs, and Protocols” table, an OMS Isolator shall select from the corresponding protocols/APIs in column C of the “Data Transfer Formats, APIs, and Protocols” table for exclusive use data transfers that cross the OMS-facing Isolator boundary.] | C30: =AND((OR(IF(F30=TRUE,TRUE,FALSE),IF(F30="N/A",TRUE,FALSE))),H30=TRUE) -> TRUE | F30: N/A | G30: (-1) | H30: =AND(M30) -> TRUE | I30: STD-006940 (-1): This requirement is verified by inspection of the Service Contract for the Isolator for each data transfer that crosses the OMS-facing Isolator boundary; the data type per column A and the protocol/API per column C is identified for each data transfer and compared to the permitted combinations listed in the “Data Transfer Formats, APIs, and Protocols” table; the inspection results are recorded in the appropriate tabs of the Isolator Checklist, OMSC-CHK-006. | J30: 1, 2, 3 | K30: Data transfers that use one of the permitted combinations per the “Data Transfer Formats, APIs, and Protocols” table are recorded in the [[OMS Data Transfer]] tab; data transfers not using one of the permitted combinations are recorded in the [[Non-OMS Data Transfer]] tab of the Isolator Checklist. If the protocols, APIs, and/or formats listed in the “Data Transfer Formats, APIs, and Protocols” table are not sufficient, an explanation as to why that is so should be captured in the “Data Transfer” section of the Service Contract. Details of any non-proprietary protocol, data format, or API that is not represented in the “Data Transfer Formats, APIs, and Protocols” table should be fully documented (or provide corresponding reference(s)) in the “Data Transfer” section of the Service Contract. The following restrictions apply for all OMS Data Transfer combinations: 1) does not overlap with OMS Messages, 2) does not overlap with any other OMS Data Exchanges, and 3) does not transfer external standards second hand. Non-OMS Data Transfers are typically restricted to OMS compliance Tier 1. However, when an OACWG-approved Change Request is identified, then the Non-OMS Data Transfer will be assessed at the maximum allowed Tier specified by the OACWG. | L30: (-1)_1 (-1)_2 (-1)_3 (-1)_4 | M30: =AND(OR(IF(P30=TRUE,TRUE,FALSE),(IF(P30="N/A",NOT(ISBLANK(Q30))))),(OR(IF(P31=TRUE,TRUE,FALSE),(IF(P31="N/A",NOT(ISBLANK(Q31)))))),(OR(IF(P32=TRUE,TRUE,FALSE),(IF(P32="N/A",NOT(ISBLANK(Q32)))))),(OR(IF(P33=TRUE,TRUE,FALSE),(IF(P33="N/A",NOT(ISBLANK(Q33))))))) -> TRUE | N30: STD-006940 (-1)_1: If, for each data transfer crossing the OMS-facing Isolator boundary, the [[OMS Data Transfer]] tab of the Isolator Checklist shows that the protocol/API in column C corresponds to the data type per column A as listed in the “Data Transfer Formats, APIs, and Protocols” table, including conforming to specified restrictions, then this VR is satisfied. | O30: Isolator Checklist | P30: ='OMS Data Transfer'!T34 -> N/A | Q30: ='OMS Data Transfer'!U34 -> No OMS Data Transfer
N31: STD-006940 (-1)_2: Each data transfer using a data type/protocol or API combination that is not listed in the “Data Transfer Formats, APIs, and Protocols” table, but is covered by the “Non-OMS Data Transfers” table, is identified in the [[Non-OMS Data Transfer]] tab. | O31: Isolator Checklist | P31: ='Non-OMS Data Transfer'!V26 -> N/A | Q31: ='Non-OMS Data Transfer'!W26 -> Invalid or No Non-OMS Combination for Data Type and Formats
N32: STD-006940 (-1)_3: A description of the data format is provided for each Non-OMS Data Transfer listed in the [[Non-OMS Data Transfer]] tab. | O32: Isolator Checklist | P32: ='Non-OMS Data Transfer'!V30 -> N/A | Q32: ='Non-OMS Data Transfer'!W30 -> Invalid or No Non-OMS Combination for Data Type and Formats
N33: STD-006940 (-1)_4: A rationale is provided for each Non-OMS Data Transfer listed in the [[Non-OMS Data Transfer]] tab explaining why the data transfer could not be implemented using a permitted combination per the “Data Transfer Formats, APIs, and Protocols” table. | O33: Isolator Checklist | P33: ='Non-OMS Data Transfer'!V31 -> N/A | Q33: ='Non-OMS Data Transfer'!W31 -> Invalid or No Non-OMS Combination for Data Type and Formats
A34: STD-006940 Tier 3 | B34: RQMT STD-006940 [For each data type identified in column A of the “Data Transfer Formats, APIs, and Protocols” table, an OMS Isolator shall select from the corresponding protocols/APIs in column C of the “Data Transfer Formats, APIs, and Protocols” table for exclusive use data transfers that cross the OMS-facing Isolator boundary.] | C34: =AND((OR(IF(F34=TRUE,TRUE,FALSE),IF(F34="N/A",TRUE,FALSE))),H34=TRUE) -> TRUE | F34: N/A | G34: (-1) (-2) (-3) | H34: =AND(M30,M34,M35) -> TRUE | I34: STD-006940 (-2): This requirement is verified by inspection of the Service Contract documentation for each data transfer that crosses the OMS-facing Isolator boundary; the data type per column A and the protocols/APIs per column C are identified for each data transfer and compared to the permitted combinations listed in the “Data Transfer Formats, APIs, and Protocols” table where the Max Assessed Tier value in column F is 3; the inspection results are recorded in the appropriate tabs of the Isolator Checklist, OMSC-CHK-006. | J34: 3 | K34: Data transfers that use one of the permitted combinations for Max Assessed Tier of 3 per the “Data Transfer Formats, APIs, and Protocols” table are recorded in the [[OMS Data Transfer]] tab. | L34: (-2)_1 | M34: =AND(OR(IF(P34=TRUE,TRUE,FALSE),(IF(P34="N/A",NOT(ISBLANK(Q34)))))) -> TRUE | N34: STD-006940 (-2)_1: If, for each data transfer crossing the OMS-facing Isolator boundary, the [[OMS Data Transfer]] tab of the Isolator Checklist shows that the protocol/API in column C corresponds to the data type per column A as listed in the “Data Transfer Formats, APIs, and Protocols” table where the Max Assessed Tier value in column F is 3, then this VR is satisfied. | O34: Isolator Checklist | P34: ='OMS Data Transfer'!T32 -> TRUE | Q34: Auto Calculated
I35: STD-006940 (-3): This requirement is verified by inspection of the Change Request documentation which adds each data type and protocol/API combination listed in the [[Non-OMS Data Transfer]] tab of the Isolator Checklist, OMSC-CHK-006. | J35: 3 | K35: Submission of a Change Request is required to: 1. Add a format, protocol, or API, or 2. Use an existing OMS format, protocol, or API to transfer a type of data not covered by the “Data Transfer Formats, APIs, and Protocols” table. This Change Request will be considered part of compliance verification and validation. The following artifacts should be reviewed as part of the Change Request during the OACWG change process: 1. Full definition of any Data Transfer formats, protocols, and APIs proposed to be changed/added/deleted. 2. Red-lined versions of all Standard documentation affected by the change. 3. Test plan that shows testing or use of these Data Transfer formats and any progress should be included. 4. Response to any issues where this material is presented. It is the expectation that the Isolator is using the Change Request update as approved by the OACWG. | L35: (-3)_1 (-3)_2 (-3)_3 | M35: =AND(OR(IF(P35=TRUE,TRUE,FALSE),(IF(P35="N/A",NOT(ISBLANK(Q35))))),(OR(IF(P36=TRUE,TRUE,FALSE),(IF(P36="N/A",NOT(ISBLANK(Q36)))))),(OR(IF(P37=TRUE,TRUE,FALSE),(IF(P37="N/A",NOT(ISBLANK(Q37))))))) -> TRUE | N35: STD-006940 (-3)_1: If there are no Non-OMS Data Transfers listed in the [[Non-OMS Data Transfer]] tab, then this VR is satisfied. | O35: Isolator Checklist | P35: ='Non-OMS Data Transfer'!V33 -> TRUE | Q35: Auto Calculated
N36: STD-006940 (-3)_2: A Change Request documenting each Non-OMS Data Transfer identified in the [[Non-OMS Data Transfer]] tab and adding the required changes to the “Data Transfer Formats, APIs, and Protocols” table where the Max Assessed Tier value in column F is 3 has been submitted to and approved by the OACWG for the Change Request. | O36: Change Request | P36: ='Non-OMS Data Transfer'!V34 -> N/A | Q36: ='Non-OMS Data Transfer'!W34 -> Invalid or No Non-OMS Combination for Data Type and Formats
N37: STD-006940 (-3)_3: The Change Request ID of the Change Request has been documented in the [[Non-OMS Data Transfer]] tab. | O37: Isolator Checklist | P37: ='Non-OMS Data Transfer'!V36 -> N/A | Q37: ='Non-OMS Data Transfer'!W36 -> Invalid or No Non-OMS Combination for Data Type and Formats
A38: STD-010121 Tier 1, 2, 3 | B38: RQMT STD-010121 [For each data type identified in column A of the “Data Transfer Formats, APIs, and Protocols” table, an OMS Isolator shall select from the corresponding protocols/APIs in column D of the “Data Transfer Formats, APIs, and Protocols” table for shared read-only data transfers that cross the OMS-facing Isolator boundary.] | C38: =AND((OR(IF(F38=TRUE,TRUE,FALSE),IF(F38="N/A",TRUE,FALSE))),H38=TRUE) -> TRUE | F38: N/A | G38: (-1) | H38: =AND(M38) -> TRUE | I38: STD-010121 (-1): This requirement is verified by inspection of the Service Contract for the Isolator for each data transfer that crosses the OMS-facing Isolator boundary; the data type per column A and the protocol/API per column D is identified for each data transfer and compared to the permitted combinations listed in the “Data Transfer Formats, APIs, and Protocols” table; the inspection results are recorded in the appropriate tabs of the Isolator Checklist, OMSC-CHK-006. | J38: 1, 2, 3 | K38: Data transfers that use one of the permitted combinations per the “Data Transfer Formats, APIs, and Protocols” table are recorded in the [[OMS Data Transfer]] tab; data transfers not using one of the permitted combinations are recorded in the [[Non-OMS Data Transfer]] tab of the Isolator Checklist. If the protocols, APIs, and/or formats listed in the “Data Transfer Formats, APIs, and Protocols” table are not sufficient, an explanation as to why that is so should be captured in the “Data Transfer” section of the Service Contract. Details of any non-proprietary protocol, data format, or API that is not represented in the “Data Transfer Formats, APIs, and Protocols” table should be fully documented (or provide corresponding reference(s)) in the “Data Transfer” section of the Service Contract. The following restrictions apply for all OMS Data Transfer combinations: 1) does not overlap with OMS Messages, 2) does not overlap with any other OMS Data Exchanges, and 3) does not transfer external standards second hand. Non-OMS Data Transfers are typically restricted to OMS compliance Tier 1. However, when an OACWG-approved Change Request is identified, then the Non-OMS Data Transfer will be assessed at the maximum allowed Tier specified by the OACWG. | L38: (-1)_1 (-1)_2 (-1)_3 (-1)_4 | M38: =AND(OR(IF(P38=TRUE,TRUE,FALSE),(IF(P38="N/A",NOT(ISBLANK(Q38))))),(OR(IF(P39=TRUE,TRUE,FALSE),(IF(P39="N/A",NOT(ISBLANK(Q39)))))),(OR(IF(P40=TRUE,TRUE,FALSE),(IF(P40="N/A",NOT(ISBLANK(Q40)))))),(OR(IF(P41=TRUE,TRUE,FALSE),(IF(P41="N/A",NOT(ISBLANK(Q41))))))) -> TRUE | N38: STD-010121 (-1)_1: If, for each data transfer crossing the OMS-facing Isolator boundary, the [[OMS Data Transfer]] tab of the Isolator Checklist shows that the protocol/API in column D corresponds to the data type per column A as listed in the “Data Transfer Formats, APIs, and Protocols” table, including conforming to specified restrictions, then this VR is satisfied. | O38: Isolator Checklist | P38: ='OMS Data Transfer'!T35 -> N/A | Q38: ='OMS Data Transfer'!U35 -> No OMS Data Transfer
N39: STD-010121 (-1)_2: Each data transfer using a data type/protocol or API combination that is not listed in the “Data Transfer Formats, APIs, and Protocols” table, but is covered by the “Non-OMS Data Transfers” table, is identified in the [[Non-OMS Data Transfer]] tab. | O39: Isolator Checklist | P39: ='Non-OMS Data Transfer'!V27 -> N/A | Q39: ='Non-OMS Data Transfer'!W27 -> Invalid or No Non-OMS Combination for Data Type and Formats
N40: STD-010121 (-1)_3: A description of the data format is provided for each Non-OMS Data Transfer listed in the [[Non-OMS Data Transfer]] tab. | O40: Isolator Checklist | P40: ='Non-OMS Data Transfer'!V30 -> N/A | Q40: ='Non-OMS Data Transfer'!W30 -> Invalid or No Non-OMS Combination for Data Type and Formats
...

Sheet Service Contract
A2: Service Contract Compliant to OMSC-TMP-003, Revision M, dated 22 January 2026? | B2: =AND(TRUE,F5,F6,F7,F8,F9,F13,F14,F15,F67,F73,F210,F212,F214,F222,F224,F226,F228) -> FALSE
A4: Service Contract Template Item | B4: Compliance | C4: Per Template? | D4: N/A Rationale | E4: Compliance Met? | F4: Section Rollup | G4: Level | H4: Row
A5: <REQUIRED: Service Contract Title> | B5: Required | C5: <Select> | E5: =IF($B5="Required",OR($C5=TRUE,AND($C5="N/A",NOT(ISBLANK($D5)))),IF($B5="Optional",TRUE,IF($B5="Required if applicable",OR($C5=TRUE,AND($C5="N/A",NOT(ISBLANK($D5)))),OR($C5=TRUE,AND($C5="N/A",NOT(ISBLANK($D5))))))) -> FALSE | F5: =AND(E5) -> FALSE | G5: 1 | H5: 5
A6: <REQUIRED: Date as DD Month YYYY> | B6: Required | C6: <Select> | E6: =IF($B6="Required",OR($C6=TRUE,AND($C6="N/A",NOT(ISBLANK($D6)))),IF($B6="Optional",TRUE,IF($B6="Required if applicable",OR($C6=TRUE,AND($C6="N/A",NOT(ISBLANK($D6)))),OR($C6=TRUE,AND($C6="N/A",NOT(ISBLANK($D6))))))) -> FALSE | F6: =AND(E6) -> FALSE | G6: 1 | H6: 6
A7: <REQUIRED: Organization> | B7: Required | C7: <Select> | E7: =IF($B7="Required",OR($C7=TRUE,AND($C7="N/A",NOT(ISBLANK($D7)))),IF($B7="Optional",TRUE,IF($B7="Required if applicable",OR($C7=TRUE,AND($C7="N/A",NOT(ISBLANK($D7)))),OR($C7=TRUE,AND($C7="N/A",NOT(ISBLANK($D7))))))) -> FALSE | F7: =AND(E7) -> FALSE | G7: 1 | H7: 7
A8: Required statements (may be more restrictive): DISCLAIMER: The discussion of non-federal entities, methods, products, or services does not imply any endorsement by the United States Government, the Department of Defense, or the Department of the Air Force. Distribution Statement A. Approved for public release: distribution is unlimited. | B8: Required | C8: <Select> | E8: =IF($B8="Required",OR($C8=TRUE,AND($C8="N/A",NOT(ISBLANK($D8)))),IF($B8="Optional",TRUE,IF($B8="Required if applicable",OR($C8=TRUE,AND($C8="N/A",NOT(ISBLANK($D8)))),OR($C8=TRUE,AND($C8="N/A",NOT(ISBLANK($D8))))))) -> FALSE | F8: =AND(E8) -> FALSE | G8: 1 | H8: 8
A9: Abstract | B9: Required | C9: <Select> | E9: =IF($B9="Required",OR($C9=TRUE,AND($C9="N/A",NOT(ISBLANK($D9)))),IF($B9="Optional",TRUE,IF($B9="Required if applicable",OR($C9=TRUE,AND($C9="N/A",NOT(ISBLANK($D9)))),OR($C9=TRUE,AND($C9="N/A",NOT(ISBLANK($D9))))))) -> FALSE | F9: =AND(E9,F10,F11,F12) -> FALSE | G9: 1 | H9: 9
A10: Open Mission Systems (OMS) is a non-proprietary open architecture for integrating subsystems and services into mission packages. | B10: Required | C10: <Select> | E10: =IF($B10="Required",OR($C10=TRUE,AND($C10="N/A",NOT(ISBLANK($D10)))),IF($B10="Optional",TRUE,IF($B10="Required if applicable",OR($C10=TRUE,AND($C10="N/A",NOT(ISBLANK($D10)))),OR($C10=TRUE,AND($C10="N/A",NOT(ISBLANK($D10))))))) -> FALSE | F10: =AND(E10) -> FALSE | G10: 2 | H10: 10
A11: This Service Contract complies with the Service Contract Template, OMSC-TMP-003, Revision M, dated 22 January 2026. | B11: Required | C11: <Select> | E11: =IF($B11="Required",OR($C11=TRUE,AND($C11="N/A",NOT(ISBLANK($D11)))),IF($B11="Optional",TRUE,IF($B11="Required if applicable",OR($C11=TRUE,AND($C11="N/A",NOT(ISBLANK($D11)))),OR($C11=TRUE,AND($C11="N/A",NOT(ISBLANK($D11))))))) -> FALSE | F11: =AND(E11) -> FALSE | G11: 2 | H11: 11
A12: The template is prescribed by the OMS Standard Version 2.5, OMSC-STD-001, Revision M, dated 22 January 2026. | B12: Required | C12: <Select> | E12: =IF($B12="Required",OR($C12=TRUE,AND($C12="N/A",NOT(ISBLANK($D12)))),IF($B12="Optional",TRUE,IF($B12="Required if applicable",OR($C12=TRUE,AND($C12="N/A",NOT(ISBLANK($D12)))),OR($C12=TRUE,AND($C12="N/A",NOT(ISBLANK($D12))))))) -> FALSE | F12: =AND(E12) -> FALSE | G12: 2 | H12: 12
A13: Revision Record | B13: Required | C13: <Select> | E13: =IF($B13="Required",OR($C13=TRUE,AND($C13="N/A",NOT(ISBLANK($D13)))),IF($B13="Optional",TRUE,IF($B13="Required if applicable",OR($C13=TRUE,AND($C13="N/A",NOT(ISBLANK($D13)))),OR($C13=TRUE,AND($C13="N/A",NOT(ISBLANK($D13))))))) -> FALSE | F13: =AND(E13) -> FALSE | G13: 1 | H13: 13
A14: Proprietary Notice: This document contains only non-proprietary information. Referenced documents conform to the Proprietary Notice statement for each major sub section. | B14: Required | C14: <Select> | E14: =IF($B14="Required",OR($C14=TRUE,AND($C14="N/A",NOT(ISBLANK($D14)))),IF($B14="Optional",TRUE,IF($B14="Required if applicable",OR($C14=TRUE,AND($C14="N/A",NOT(ISBLANK($D14)))),OR($C14=TRUE,AND($C14="N/A",NOT(ISBLANK($D14))))))) -> FALSE | F14: =AND(E14) -> FALSE | G14: 1 | H14: 14
A15: 1 Overview | B15: Required | C15: <Select> | E15: =IF($B15="Required",OR($C15=TRUE,AND($C15="N/A",NOT(ISBLANK($D15)))),IF($B15="Optional",TRUE,IF($B15="Required if applicable",OR($C15=TRUE,AND($C15="N/A",NOT(ISBLANK($D15)))),OR($C15=TRUE,AND($C15="N/A",NOT(ISBLANK($D15))))))) -> FALSE | F15: =AND(E15,F16,F17,F20,F27,F28,F29,F35,F50,F52,F54,F60,F64) -> FALSE | G15: 1 | H15: 15
A16: Proprietary Notice: References to external documents that provide for the data in this section refer only to non-proprietary documents, except where otherwise noted in specific sub-sections that may refer to proprietary documents. | B16: Required | C16: <Select> | E16: =IF($B16="Required",OR($C16=TRUE,AND($C16="N/A",NOT(ISBLANK($D16)))),IF($B16="Optional",TRUE,IF($B16="Required if applicable",OR($C16=TRUE,AND($C16="N/A",NOT(ISBLANK($D16)))),OR($C16=TRUE,AND($C16="N/A",NOT(ISBLANK($D16))))))) -> FALSE | F16: =AND(E16) -> FALSE | G16: 2 | H16: 16
A17: 1.1 References | B17: Required | C17: <Select> | E17: =IF($B17="Required",OR($C17=TRUE,AND($C17="N/A",NOT(ISBLANK($D17)))),IF($B17="Optional",TRUE,IF($B17="Required if applicable",OR($C17=TRUE,AND($C17="N/A",NOT(ISBLANK($D17)))),OR($C17=TRUE,AND($C17="N/A",NOT(ISBLANK($D17))))))) -> FALSE | F17: =AND(E17,F18,F19) -> FALSE | G17: 2 | H17: 17
A18: Proprietary Notice: References to external documents that provide for the data in this section may refer to proprietary documents. | B18: Required | C18: <Select> | E18: =IF($B18="Required",OR($C18=TRUE,AND($C18="N/A",NOT(ISBLANK($D18)))),IF($B18="Optional",TRUE,IF($B18="Required if applicable",OR($C18=TRUE,AND($C18="N/A",NOT(ISBLANK($D18)))),OR($C18=TRUE,AND($C18="N/A",NOT(ISBLANK($D18))))))) -> FALSE | F18: =AND(E18) -> FALSE | G18: 3 | H18: 18
A19: Table 1.1-1 Reference Documents | B19: Required | C19: <Select> | E19: =IF($B19="Required",OR($C19=TRUE,AND($C19="N/A",NOT(ISBLANK($D19)))),IF($B19="Optional",TRUE,IF($B19="Required if applicable",OR($C19=TRUE,AND($C19="N/A",NOT(ISBLANK($D19)))),OR($C19=TRUE,AND($C19="N/A",NOT(ISBLANK($D19))))))) -> FALSE | F19: =AND(E19) -> FALSE | G19: 3 | H19: 19
A20: 1.2 OMS Environment Specifications | B20: Required | C20: <Select> | E20: =IF($B20="Required",OR($C20=TRUE,AND($C20="N/A",NOT(ISBLANK($D20)))),IF($B20="Optional",TRUE,IF($B20="Required if applicable",OR($C20=TRUE,AND($C20="N/A",NOT(ISBLANK($D20)))),OR($C20=TRUE,AND($C20="N/A",NOT(ISBLANK($D20))))))) -> FALSE | F20: =AND(E20,F21,F22,F23,F25) -> FALSE | G20: 2 | H20: 20
A21: Table 1.2-1 Environment Specifications | B21: Required | C21: <Select> | E21: =IF($B21="Required",OR($C21=TRUE,AND($C21="N/A",NOT(ISBLANK($D21)))),IF($B21="Optional",TRUE,IF($B21="Required if applicable",OR($C21=TRUE,AND($C21="N/A",NOT(ISBLANK($D21)))),OR($C21=TRUE,AND($C21="N/A",NOT(ISBLANK($D21))))))) -> FALSE | F21: =AND(E21) -> FALSE | G21: 3 | H21: 21
A22: Table 1.2-2 OMS Message Set | B22: Required | C22: <Select> | E22: =IF($B22="Required",OR($C22=TRUE,AND($C22="N/A",NOT(ISBLANK($D22)))),IF($B22="Optional",TRUE,IF($B22="Required if applicable",OR($C22=TRUE,AND($C22="N/A",NOT(ISBLANK($D22)))),OR($C22=TRUE,AND($C22="N/A",NOT(ISBLANK($D22))))))) -> FALSE | F22: =AND(E22) -> FALSE | G22: 3 | H22: 22
A23: 1.2.1 Externalizer Specifications | B23: Required | C23: <Select> | E23: =IF($B23="Required",OR($C23=TRUE,AND($C23="N/A",NOT(ISBLANK($D23)))),IF($B23="Optional",TRUE,IF($B23="Required if applicable",OR($C23=TRUE,AND($C23="N/A",NOT(ISBLANK($D23)))),OR($C23=TRUE,AND($C23="N/A",NOT(ISBLANK($D23))))))) -> FALSE | F23: =AND(E23,F24) -> FALSE | G23: 3 | H23: 23
A24: Table 1.2-3 Externalizer Version Information | B24: Required | C24: <Select> | E24: =IF($B24="Required",OR($C24=TRUE,AND($C24="N/A",NOT(ISBLANK($D24)))),IF($B24="Optional",TRUE,IF($B24="Required if applicable",OR($C24=TRUE,AND($C24="N/A",NOT(ISBLANK($D24)))),OR($C24=TRUE,AND($C24="N/A",NOT(ISBLANK($D24))))))) -> FALSE | F24: =AND(E24) -> FALSE | G24: 4 | H24: 24
A25: 1.2.2 CAL Operational Attributes | B25: Required | C25: <Select> | E25: =IF($B25="Required",OR($C25=TRUE,AND($C25="N/A",NOT(ISBLANK($D25)))),IF($B25="Optional",TRUE,IF($B25="Required if applicable",OR($C25=TRUE,AND($C25="N/A",NOT(ISBLANK($D25)))),OR($C25=TRUE,AND($C25="N/A",NOT(ISBLANK($D25))))))) -> FALSE | F25: =AND(E25,F26) -> FALSE | G25: 3 | H25: 25
A26: Table 1.2-4 SOAC-1 | B26: Required | C26: <Select> | E26: =IF($B26="Required",OR($C26=TRUE,AND($C26="N/A",NOT(ISBLANK($D26)))),IF($B26="Optional",TRUE,IF($B26="Required if applicable",OR($C26=TRUE,AND($C26="N/A",NOT(ISBLANK($D26)))),OR($C26=TRUE,AND($C26="N/A",NOT(ISBLANK($D26))))))) -> FALSE | F26: =AND(E26) -> FALSE | G26: 4 | H26: 26
A27: 1.3 Classification | B27: Required | C27: <Select> | E27: =IF($B27="Required",OR($C27=TRUE,AND($C27="N/A",NOT(ISBLANK($D27)))),IF($B27="Optional",TRUE,IF($B27="Required if applicable",OR($C27=TRUE,AND($C27="N/A",NOT(ISBLANK($D27)))),OR($C27=TRUE,AND($C27="N/A",NOT(ISBLANK($D27))))))) -> FALSE | F27: =AND(E27) -> FALSE | G27: 2 | H27: 27
A28: 1.4 Known Limitations | B28: Required | C28: <Select> | E28: =IF($B28="Required",OR($C28=TRUE,AND($C28="N/A",NOT(ISBLANK($D28)))),IF($B28="Optional",TRUE,IF($B28="Required if applicable",OR($C28=TRUE,AND($C28="N/A",NOT(ISBLANK($D28)))),OR($C28=TRUE,AND($C28="N/A",NOT(ISBLANK($D28))))))) -> FALSE | F28: =AND(E28) -> FALSE | G28: 2 | H28: 28
A29: 1.5 System Requirements | B29: Required | C29: <Select> | E29: =IF($B29="Required",OR($C29=TRUE,AND($C29="N/A",NOT(ISBLANK($D29)))),IF($B29="Optional",TRUE,IF($B29="Required if applicable",OR($C29=TRUE,AND($C29="N/A",NOT(ISBLANK($D29)))),OR($C29=TRUE,AND($C29="N/A",NOT(ISBLANK($D29))))))) -> FALSE | F29: =AND(E29,F30,F31,F33) -> FALSE | G29: 2 | H29: 29
A30: Proprietary Notice: References to external documents that provide for the data in this section may refer to proprietary documents. | B30: Required | C30: <Select> | E30: =IF($B30="Required",OR($C30=TRUE,AND($C30="N/A",NOT(ISBLANK($D30)))),IF($B30="Optional",TRUE,IF($B30="Required if applicable",OR($C30=TRUE,AND($C30="N/A",NOT(ISBLANK($D30)))),OR($C30=TRUE,AND($C30="N/A",NOT(ISBLANK($D30))))))) -> FALSE | F30: =AND(E30) -> FALSE | G30: 3 | H30: 30
A31: 1.5.1 Hardware Requirements | B31: Required | C31: <Select> | E31: =IF($B31="Required",OR($C31=TRUE,AND($C31="N/A",NOT(ISBLANK($D31)))),IF($B31="Optional",TRUE,IF($B31="Required if applicable",OR($C31=TRUE,AND($C31="N/A",NOT(ISBLANK($D31)))),OR($C31=TRUE,AND($C31="N/A",NOT(ISBLANK($D31))))))) -> FALSE | F31: =AND(E31,F32) -> FALSE | G31: 3 | H31: 31
A32: Table 1.5-1 Hardware Requirements | B32: Required | C32: <Select> | E32: =IF($B32="Required",OR($C32=TRUE,AND($C32="N/A",NOT(ISBLANK($D32)))),IF($B32="Optional",TRUE,IF($B32="Required if applicable",OR($C32=TRUE,AND($C32="N/A",NOT(ISBLANK($D32)))),OR($C32=TRUE,AND($C32="N/A",NOT(ISBLANK($D32))))))) -> FALSE | F32: =AND(E32) -> FALSE | G32: 4 | H32: 32
A33: 1.5.2 Operating Systems | B33: Required | C33: <Select> | E33: =IF($B33="Required",OR($C33=TRUE,AND($C33="N/A",NOT(ISBLANK($D33)))),IF($B33="Optional",TRUE,IF($B33="Required if applicable",OR($C33=TRUE,AND($C33="N/A",NOT(ISBLANK($D33)))),OR($C33=TRUE,AND($C33="N/A",NOT(ISBLANK($D33))))))) -> FALSE | F33: =AND(E33,F34) -> FALSE | G33: 3 | H33: 33
A34: Table 1.5-2 Compatible Operating Systems | B34: Required | C34: <Select> | E34: =IF($B34="Required",OR($C34=TRUE,AND($C34="N/A",NOT(ISBLANK($D34)))),IF($B34="Optional",TRUE,IF($B34="Required if applicable",OR($C34=TRUE,AND($C34="N/A",NOT(ISBLANK($D34)))),OR($C34=TRUE,AND($C34="N/A",NOT(ISBLANK($D34))))))) -> FALSE | F34: =AND(E34) -> FALSE | G34: 4 | H34: 34
A35: 1.6 Data Transfer | B35: Required | C35: <Select> | E35: =IF($B35="Required",OR($C35=TRUE,AND($C35="N/A",NOT(ISBLANK($D35)))),IF($B35="Optional",TRUE,IF($B35="Required if applicable",OR($C35=TRUE,AND($C35="N/A",NOT(ISBLANK($D35)))),OR($C35=TRUE,AND($C35="N/A",NOT(ISBLANK($D35))))))) -> FALSE | F35: =AND(E35,F36,F38,F40,F42,F44,F46,F48,F49) -> FALSE | G35: 2 | H35: 35
A36: 1.6.1 Data Items for OMS Data Transfer | B36: Required | C36: <Select> | E36: =IF($B36="Required",OR($C36=TRUE,AND($C36="N/A",NOT(ISBLANK($D36)))),IF($B36="Optional",TRUE,IF($B36="Required if applicable",OR($C36=TRUE,AND($C36="N/A",NOT(ISBLANK($D36)))),OR($C36=TRUE,AND($C36="N/A",NOT(ISBLANK($D36))))))) -> FALSE | F36: =AND(E36,F37) -> FALSE | G36: 3 | H36: 36
A37: Table 1.6-1 Data Items for OMS Data Transfer | B37: Required | C37: <Select> | E37: =IF($B37="Required",OR($C37=TRUE,AND($C37="N/A",NOT(ISBLANK($D37)))),IF($B37="Optional",TRUE,IF($B37="Required if applicable",OR($C37=TRUE,AND($C37="N/A",NOT(ISBLANK($D37)))),OR($C37=TRUE,AND($C37="N/A",NOT(ISBLANK($D37))))))) -> FALSE | F37: =AND(E37) -> FALSE | G37: 4 | H37: 37
A38: 1.6.2 Data Items for Non-OMS Data Transfer | B38: Required | C38: <Select> | E38: =IF($B38="Required",OR($C38=TRUE,AND($C38="N/A",NOT(ISBLANK($D38)))),IF($B38="Optional",TRUE,IF($B38="Required if applicable",OR($C38=TRUE,AND($C38="N/A",NOT(ISBLANK($D38)))),OR($C38=TRUE,AND($C38="N/A",NOT(ISBLANK($D38))))))) -> FALSE | F38: =AND(E38,F39) -> FALSE | G38: 3 | H38: 38
A39: Table 1.6-2 Data Items for Non-OMS Data Transfer | B39: Required | C39: <Select> | E39: =IF($B39="Required",OR($C39=TRUE,AND($C39="N/A",NOT(ISBLANK($D39)))),IF($B39="Optional",TRUE,IF($B39="Required if applicable",OR($C39=TRUE,AND($C39="N/A",NOT(ISBLANK($D39)))),OR($C39=TRUE,AND($C39="N/A",NOT(ISBLANK($D39))))))) -> FALSE | F39: =AND(E39) -> FALSE | G39: 4 | H39: 39
A40: 1.6.3 Data Transfer Configuration | B40: Required | C40: <Select> | E40: =IF($B40="Required",OR($C40=TRUE,AND($C40="N/A",NOT(ISBLANK($D40)))),IF($B40="Optional",TRUE,IF($B40="Required if applicable",OR($C40=TRUE,AND($C40="N/A",NOT(ISBLANK($D40)))),OR($C40=TRUE,AND($C40="N/A",NOT(ISBLANK($D40))))))) -> FALSE | F40: =AND(E40,F41) -> FALSE | G40: 3 | H40: 40
A41: Table 1.6-3 Data Transfer Configuration | B41: Required | C41: <Select> | E41: =IF($B41="Required",OR($C41=TRUE,AND($C41="N/A",NOT(ISBLANK($D41)))),IF($B41="Optional",TRUE,IF($B41="Required if applicable",OR($C41=TRUE,AND($C41="N/A",NOT(ISBLANK($D41)))),OR($C41=TRUE,AND($C41="N/A",NOT(ISBLANK($D41))))))) -> FALSE | F41: =AND(E41) -> FALSE | G41: 4 | H41: 41
A42: 1.6.4 Data Transfer Ports and Protocols | B42: Required | C42: <Select> | E42: =IF($B42="Required",OR($C42=TRUE,AND($C42="N/A",NOT(ISBLANK($D42)))),IF($B42="Optional",TRUE,IF($B42="Required if applicable",OR($C42=TRUE,AND($C42="N/A",NOT(ISBLANK($D42)))),OR($C42=TRUE,AND($C42="N/A",NOT(ISBLANK($D42))))))) -> FALSE | F42: =AND(E42,F43) -> FALSE | G42: 3 | H42: 42
...

Sheet OMS Msgs
A1: OMS Messages | G1: Message Set | H1: Uses Applicable Tier 1 MMS | J1: Uses Applicable Tier 1 Required Subsystem | L1: Uses Applicable Tier 2 MMS | N1: Tier 3 Uses Applicable OMS Msgs | T1: Messages Documented and Tested | BP1: OMS Message - An OMS Message is a unit of information sent or received using an OMS CAL. OMS Messages are primarily command-and-control-oriented exchanges used inside of a Mission Package to coordinate key mission functionality, technical capabilities, and operational behaviors of the interaction between the Architecture Elements (Platforms, Subsystems, Services, and Isolators).
G2: Implementation | H2: =AND($I$5:$I$727) -> FALSE | J2: =AND($K$5:$K$727) -> FALSE | L2: =AND($M$5:$M$727) -> FALSE | N2: =AND($O$5:$O$727) -> FALSE | T2: =AND($W$5:$W$727) -> TRUE
A4: Valid OMS Messages UCI Schema v002.5, 22 January 2026 | B4: OMS Tier 1 MMS | C4: Tier 1 Required Subsystem Message Set | D4: OMS Tier 2 MMS | E4: Valid OMS Message | F4: Used | G4: Rationale for N/A | H4: Tier 1 MMS Compliant | I4: Check Tier 1 MMS | J4: Tier 1 Required Subsystem Compliant | K4: Check Tier 1 Subsystem | L4: Tier 2 MMS Compliant | M4: Check Tier 2 MMS | N4: Tier 3 Compliant | O4: Uses Applicable Msgs | P4: Service Contract Section | Q4: Input | R4: Output | S4: Functional Test Results Location | T4: Message Documented and Tested | U4: Change Request Identifier, if Applicable | V4: Notes | W4: If Used is Documented | X4: Msg Used | Y4: Entered SC Section | Z4: Indicated Input | AA4: Indicated Output | AB4: Entered FTR Location | AC4: Entered Applicable CR | AD4: Not Used Count | AE4: Used Count | AF4: Contains "<Select>"? | AG4: Counts | AH4: Count for all with "YES WITH MODIFICATION" | AI4: Contains "N/A" in column F | AJ4: Contains "N/A" and Rationale in column F | AK4: Contains YES WITH MODIFICATION | AL4: CR Identified | AM4: Same value for TRUE for YES WITH MODIFICATION AND CR Identified? | AN4: Count for TRUE | AO4: YES WITH MODIFICATION have CR identified? | AP4: Message Sets | AQ4: Functional Test Result Location Entered? | AR4: Message is documented and tested? | AS4: Check for "STD-000063 (-1)_2" | AT4: Check for "STD-000064 (-1)_2" | AU4: Check for "STD-000064 (-1)_3" | AV4: Count check for Tier 1 MMS YES WITH MODIFICATION | AW4: Count check for Tier 1 MMS CR Identified | AX4: Count check for Tier 1 MMS "N/A" | AY4: Count check for Tier 1 MMS Rationale Entered | AZ4: Count check for Tier 1 Sub MMS YES WITH MODIFICATION | BA4: Count check for Tier 1 Sub MMS CR Identified | BB4: Count check for Tier 1 Sub MMS "N/A" | BC4: Count check for Tier 1 Sub MMS Rationale Entered | BD4: Count check for Tier 2 MMS YES WITH MODIFICATION | BE4: Count check for Tier 2 MMS CR Identified | BF4: Count check for Tier 2 MMS "N/A" | BG4: Count check for Tier 2 MMS Rationale Entered | BH4: OMS Msgs Completed and FTR Locations are identified | BI4: Check for "STD-000074 (-2)_1" | BJ4: Check for "STD-000074 (-2)_2" | BK4: Column F row completed? | BL4: Column F Completed? | BM4: AC | BN4: Main Calculation | BO4: Input/Output Data Validation
